Workbook

Sheet MKN Slip
A5: Baan Pong Cross Country 2026
C6: BIB No : | D6: 3381
C7: Name : | D7: =IFERROR(VLOOKUP($D$6,'(3)Summary Finished'!$B$4:$O$195,3,FALSE),0) -> JANTARABOON.K
C8: Gender : | D8: =IFERROR(VLOOKUP($D$6,'(3)Summary Finished'!$B$4:$O$195,4,FALSE),0) -> Male
C9: Age Group : | D9: =IFERROR(VLOOKUP($D$6,'(3)Summary Finished'!$B$4:$O$195,5,FALSE),0) -> 20-39
C10: Category : | D10: =IFERROR(VLOOKUP($D$6,'(3)Summary Finished'!$B$4:$O$195,7,FALSE),0) -> MKT33
C11: Check in : | D11: =IFERROR(VLOOKUP($D$6,'(3)Summary Finished'!$B$4:$O$201,8,FALSE),0) -> 45550.228
C12: Start Time : | D12: =IFERROR(VLOOKUP($D$6,'(3)Summary Finished'!$B$4:$O$195,9,FALSE),0) -> 0.22916667
C13: Finish Time : | D13: =IFERROR(VLOOKUP($D$6,'(3)Summary Finished'!$B$4:$O$195,10,FALSE),0) -> 45550.37
C14: Time Result : | D14: =D13-D12 -> 45550.141 | E14: =IFERROR(VLOOKUP($D$6,'(3)Summary Finished'!$B$4:$J$158,3,FALSE),0) -> JANTARABOON.K | F14: =IFERROR(VLOOKUP($D$6,'(3)Summary Finished'!$B$4:$J$158,3,FALSE),0) -> JANTARABOON.K
C15: Overall Rank : | D15: =IFERROR(VLOOKUP($D$6,'(3)Summary Finished'!$B$4:$O$198,12,FALSE),0) -> 1 | E15: /
C16: Gender Rank : | D16: =IFERROR(VLOOKUP($D$6,'(3)Summary Finished'!$B$4:$O$198,13,FALSE),0) -> 1 | E16: /
C17: Age Group : | D17: =IFERROR(VLOOKUP($D$6,'(3)Summary Finished'!$B$4:$O$198,14,FALSE),0) -> 1 | E17: /
A18: * Provisional Result
A22: Timing System by Mea Khanin Club

Sheet (3)Summary Finished
A1: SUMMARY TIME RESULT AND RANK "Mae Khanin Trail 2024" | M1: RANK | S1: Finisher Runner
A2: No. | B2: BIB Number | C2: Name Surname, Team | D2: Name on BIB | E2: Gender | F2: Age Group | G2: Nationality | H2: Category | I2: Check in Time | J2: Start Time | K2: Finish Time | L2: Time | M2: Over all | N2: Gender | O2: Age Group
A3: ลำดับ | B3: หมายเลขแข่งขัน | C3: ชื่อ-นามสกุล หรือชื่อทีม | D3: ชื่อบนหมายเลขวิ่ง | E3: เพศ | F3: กลุ่มอายุ | G3: สัญชาติ | H3: ประเภทแข่งขัน | I3: รายงานตัวจุดปล่อยตัว | J3: เวลาปล่อยตัว | K3: เวลาสิ้นสุดการแข่งขัน | L3: เวลาที่ใช้ | M3: ลำดับรวม | N3: ลำดับเพศ | O3: ลำดับช่วงอายุ | S3: MKT33 | T3: =COUNTIF($H$4:$H$198,"MKT33") -> 66 | X3: MKT50 | Y3: =COUNTIF($H$4:$H$198,"MKT50") -> 34
A4: 1 | B4: 3381 | C4: =IFERROR(VLOOKUP(B4,'Runner List'!$B$3:$O$505,5,FALSE),0) -> JANTARABOON KIANGCHAIPAIPHANA | D4: =IFERROR(VLOOKUP(B4,'Runner List'!$B$3:$O$505,6,FALSE),0) -> JANTARABOON.K | E4: =IFERROR(VLOOKUP(B4,'Runner List'!$B$3:$O$505,7,FALSE),0) -> Male | F4: =IFERROR(VLOOKUP(B4,'Runner List'!$B$3:$O$505,8,FALSE),0) -> 20-39 | G4: =IFERROR(VLOOKUP(B4,'Runner List'!$B$3:$O$505,9,FALSE),0) -> Thai | H4: =IFERROR(VLOOKUP(B4,'Runner List'!$B$3:$O$505,10,FALSE),0) -> MKT33 | I4: =IFERROR(VLOOKUP(B4,'(2)Check In'!$B$4:$I$418,7,FALSE),0) -> 45550.228 | J4: =IFERROR(VLOOKUP(B4,'(2)Check In'!$B$4:$I$848,8,FALSE),0) -> 0.22916667 | K4: =IF(B4="","",IF(K4="",NOW(),K4)) -> 45550.37 | L4: =K4-J4 -> 45550.141 | M4: =COUNTIFS($H$3:H4,H4) -> 1 | N4: =COUNTIFS(F$3:$F4,F4,H$3:$H4,H4,E$3:$E4,E4) -> 1 | O4: =COUNTIFS($F$3:F4,F4,$H$3:H4,H4) -> 1 | S4: Male | T4: =COUNTIFS($H$4:$H$198,"MKT33",$E$4:$E$198,"Male") -> 42 | U4: 20-39 | V4: =COUNTIFS($H$4:$H$198,"MKT33",$E$4:$E$198,"Male",$F$4:$F$198,"20-39") -> 18 | X4: Male | Y4: =COUNTIFS($H$4:$H$198,"MKT50",$E$4:$E$198,"Male") -> 25 | Z4: 20-39 | AA4: =COUNTIFS($H$4:$H$198,"MKT50",$E$4:$E$198,"Male",$F$4:$F$198,"20-39") -> 3
A5: 2 | B5: 3399 | C5: =IFERROR(VLOOKUP(B5,'Runner List'!$B$3:$O$505,5,FALSE),0) -> KAMONNUT SUWANNA | D5: =IFERROR(VLOOKUP(B5,'Runner List'!$B$3:$O$505,6,FALSE),0) -> KAMONNUT.S | E5: =IFERROR(VLOOKUP(B5,'Runner List'!$B$3:$O$505,7,FALSE),0) -> Male | F5: =IFERROR(VLOOKUP(B5,'Runner List'!$B$3:$O$505,8,FALSE),0) -> 20-39 | G5: =IFERROR(VLOOKUP(B5,'Runner List'!$B$3:$O$505,9,FALSE),0) -> Thai | H5: =IFERROR(VLOOKUP(B5,'Runner List'!$B$3:$O$505,10,FALSE),0) -> MKT33 | I5: =IFERROR(VLOOKUP(B5,'(2)Check In'!$B$4:$I$848,7,FALSE),0) -> 45550.23 | J5: =IFERROR(VLOOKUP(B5,'(2)Check In'!$B$4:$I$848,8,FALSE),0) -> 0.22916667 | K5: =IF(B5="","",IF(K5="",NOW(),K5)) -> 45550.41 | L5: =K5-J5 -> 45550.181 | M5: =COUNTIFS($H$3:H5,H5) -> 2 | N5: =COUNTIFS(F$3:$F5,F5,H$3:$H5,H5,E$3:$E5,E5) -> 2 | O5: =COUNTIFS($F$3:F5,F5,$H$3:H5,H5) -> 2 | U5: 40-49 | V5: =COUNTIFS($H$4:$H$198,"MKT33",$E$4:$E$198,"Male",$F$4:$F$198,"40-49") -> 11 | Z5: 40-49 | AA5: =COUNTIFS($H$4:$H$198,"MKT50",$E$4:$E$198,"Male",$F$4:$F$198,"40-49") -> 14
A6: 3 | B6: 3330 | C6: =IFERROR(VLOOKUP(B6,'Runner List'!$B$3:$O$505,5,FALSE),0) -> NUTTAWUT SUPANURAT | D6: =IFERROR(VLOOKUP(B6,'Runner List'!$B$3:$O$505,6,FALSE),0) -> NUTTAWUT.S | E6: =IFERROR(VLOOKUP(B6,'Runner List'!$B$3:$O$505,7,FALSE),0) -> Male | F6: =IFERROR(VLOOKUP(B6,'Runner List'!$B$3:$O$505,8,FALSE),0) -> 40-49 | G6: =IFERROR(VLOOKUP(B6,'Runner List'!$B$3:$O$505,9,FALSE),0) -> Thai | H6: =IFERROR(VLOOKUP(B6,'Runner List'!$B$3:$O$505,10,FALSE),0) -> MKT33 | I6: =IFERROR(VLOOKUP(B6,'(2)Check In'!$B$4:$I$848,7,FALSE),0) -> 45550.227 | J6: =IFERROR(VLOOKUP(B6,'(2)Check In'!$B$4:$I$848,8,FALSE),0) -> 0.22916667 | K6: =IF(B6="","",IF(K6="",NOW(),K6)) -> 45550.411 | L6: =K6-J6 -> 45550.182 | M6: =COUNTIFS($H$3:H6,H6) -> 3 | N6: =COUNTIFS(F$3:$F6,F6,H$3:$H6,H6,E$3:$E6,E6) -> 1 | O6: =COUNTIFS($F$3:F6,F6,$H$3:H6,H6) -> 1 | U6: 50-59 | V6: =COUNTIFS($H$4:$H$198,"MKT33",$E$4:$E$198,"Male",$F$4:$F$198,"50-59") -> 11 | Z6: 50-59 | AA6: =COUNTIFS($H$4:$H$198,"MKT50",$E$4:$E$198,"Male",$F$4:$F$198,"50-59") -> 5
A7: 4 | B7: 3388 | C7: =IFERROR(VLOOKUP(B7,'Runner List'!$B$3:$O$505,5,FALSE),0) -> WORAWUT PHUENGPHOCHAROENPHAN | D7: =IFERROR(VLOOKUP(B7,'Runner List'!$B$3:$O$505,6,FALSE),0) -> WORAWUT.P | E7: =IFERROR(VLOOKUP(B7,'Runner List'!$B$3:$O$505,7,FALSE),0) -> Male | F7: =IFERROR(VLOOKUP(B7,'Runner List'!$B$3:$O$505,8,FALSE),0) -> 40-49 | G7: =IFERROR(VLOOKUP(B7,'Runner List'!$B$3:$O$505,9,FALSE),0) -> Thai | H7: =IFERROR(VLOOKUP(B7,'Runner List'!$B$3:$O$505,10,FALSE),0) -> MKT33 | I7: =IFERROR(VLOOKUP(B7,'(2)Check In'!$B$4:$I$848,7,FALSE),0) -> 45550.227 | J7: =IFERROR(VLOOKUP(B7,'(2)Check In'!$B$4:$I$848,8,FALSE),0) -> 0.22916667 | K7: =IF(B7="","",IF(K7="",NOW(),K7)) -> 45550.423 | L7: =K7-J7 -> 45550.194 | M7: =COUNTIFS($H$3:H7,H7) -> 4 | N7: =COUNTIFS(F$3:$F7,F7,H$3:$H7,H7,E$3:$E7,E7) -> 2 | O7: =COUNTIFS($F$3:F7,F7,$H$3:H7,H7) -> 2 | S7: Female | T7: =COUNTIFS($H$4:$H$198,"MKT33",$E$4:$E$198,"Female") -> 22 | U7: 20-39 | V7: =COUNTIFS($H$4:$H$198,"MKT33",$E$4:$E$198,"Female",$F$4:$F$198,"20-39") -> 12 | X7: Female | Y7: =COUNTIFS($H$4:$H$198,"MKT50",$E$4:$E$198,"Female") -> 8 | Z7: 20-39 | AA7: =COUNTIFS($H$4:$H$198,"MKT50",$E$4:$E$198,"Female",$F$4:$F$198,"20-39") -> 0
A8: 5 | B8: 3350 | C8: =IFERROR(VLOOKUP(B8,'Runner List'!$B$3:$O$505,5,FALSE),0) -> STEFAN ENGEL | D8: =IFERROR(VLOOKUP(B8,'Runner List'!$B$3:$O$505,6,FALSE),0) -> STEFAN ENGEL | E8: =IFERROR(VLOOKUP(B8,'Runner List'!$B$3:$O$505,7,FALSE),0) -> Male | F8: =IFERROR(VLOOKUP(B8,'Runner List'!$B$3:$O$505,8,FALSE),0) -> 40-49 | G8: =IFERROR(VLOOKUP(B8,'Runner List'!$B$3:$O$505,9,FALSE),0) -> Swiss | H8: =IFERROR(VLOOKUP(B8,'Runner List'!$B$3:$O$505,10,FALSE),0) -> MKT33 | I8: =IFERROR(VLOOKUP(B8,'(2)Check In'!$B$4:$I$848,7,FALSE),0) -> 45550.227 | J8: =IFERROR(VLOOKUP(B8,'(2)Check In'!$B$4:$I$848,8,FALSE),0) -> 0.22916667 | K8: =IF(B8="","",IF(K8="",NOW(),K8)) -> 45550.426 | L8: =K8-J8 -> 45550.197 | M8: =COUNTIFS($H$3:H8,H8) -> 5 | N8: =COUNTIFS(F$3:$F8,F8,H$3:$H8,H8,E$3:$E8,E8) -> 3 | O8: =COUNTIFS($F$3:F8,F8,$H$3:H8,H8) -> 3 | U8: 40-49 | V8: =COUNTIFS($H$4:$H$198,"MKT33",$E$4:$E$198,"Female",$F$4:$F$198,"40-49") -> 5 | Z8: 40-49 | AA8: =COUNTIFS($H$4:$H$198,"MKT50",$E$4:$E$198,"Female",$F$4:$F$198,"40-49") -> 3
A9: 6 | B9: 3379 | C9: =IFERROR(VLOOKUP(B9,'Runner List'!$B$3:$O$505,5,FALSE),0) -> ITTIPON UPPAPONG | D9: =IFERROR(VLOOKUP(B9,'Runner List'!$B$3:$O$505,6,FALSE),0) -> ITTIPON.U | E9: =IFERROR(VLOOKUP(B9,'Runner List'!$B$3:$O$505,7,FALSE),0) -> Male | F9: =IFERROR(VLOOKUP(B9,'Runner List'!$B$3:$O$505,8,FALSE),0) -> 20-39 | G9: =IFERROR(VLOOKUP(B9,'Runner List'!$B$3:$O$505,9,FALSE),0) -> Thai | H9: =IFERROR(VLOOKUP(B9,'Runner List'!$B$3:$O$505,10,FALSE),0) -> MKT33 | I9: =IFERROR(VLOOKUP(B9,'(2)Check In'!$B$4:$I$848,7,FALSE),0) -> 45550.226 | J9: =IFERROR(VLOOKUP(B9,'(2)Check In'!$B$4:$I$848,8,FALSE),0) -> 0.22916667 | K9: =IF(B9="","",IF(K9="",NOW(),K9)) -> 45550.432 | L9: =K9-J9 -> 45550.203 | M9: =COUNTIFS($H$3:H9,H9) -> 6 | N9: =COUNTIFS(F$3:$F9,F9,H$3:$H9,H9,E$3:$E9,E9) -> 3 | O9: =COUNTIFS($F$3:F9,F9,$H$3:H9,H9) -> 3 | U9: 50-59 | V9: =COUNTIFS($H$4:$H$198,"MKT33",$E$4:$E$198,"Female",$F$4:$F$198,"50-59") -> 4 | Z9: 50-59 | AA9: =COUNTIFS($H$4:$H$198,"MKT50",$E$4:$E$198,"Female",$F$4:$F$198,"50-59") -> 4
A10: 7 | B10: 3301 | C10: =IFERROR(VLOOKUP(B10,'Runner List'!$B$3:$O$505,5,FALSE),0) -> BLAKE WICHTOWSKI | D10: =IFERROR(VLOOKUP(B10,'Runner List'!$B$3:$O$505,6,FALSE),0) -> BLAKE WICHTOWSKI | E10: =IFERROR(VLOOKUP(B10,'Runner List'!$B$3:$O$505,7,FALSE),0) -> Male | F10: =IFERROR(VLOOKUP(B10,'Runner List'!$B$3:$O$505,8,FALSE),0) -> 20-39 | G10: =IFERROR(VLOOKUP(B10,'Runner List'!$B$3:$O$505,9,FALSE),0) -> Thai | H10: =IFERROR(VLOOKUP(B10,'Runner List'!$B$3:$O$505,10,FALSE),0) -> MKT33 | I10: =IFERROR(VLOOKUP(B10,'(2)Check In'!$B$4:$I$848,7,FALSE),0) -> 45550.226 | J10: =IFERROR(VLOOKUP(B10,'(2)Check In'!$B$4:$I$848,8,FALSE),0) -> 0.22916667 | K10: =IF(B10="","",IF(K10="",NOW(),K10)) -> 45550.434 | L10: =K10-J10 -> 45550.205 | M10: =COUNTIFS($H$3:H10,H10) -> 7 | N10: =COUNTIFS(F$3:$F10,F10,H$3:$H10,H10,E$3:$E10,E10) -> 4 | O10: =COUNTIFS($F$3:F10,F10,$H$3:H10,H10) -> 4 | U10: 60 Plus | V10: =COUNTIFS($H$4:$H$198,"MKT33",$E$4:$E$198,"Female",$F$4:$F$198,"60 Plus") -> 1 | Z10: 60 Plus | AA10: =COUNTIFS($H$4:$H$198,"MKT50",$E$4:$E$198,"Female",$F$4:$F$198,"60 Plus") -> 1
A11: 8 | B11: 3395 | C11: =IFERROR(VLOOKUP(B11,'Runner List'!$B$3:$O$505,5,FALSE),0) -> BANCHAPOL DHIRANETRA | D11: =IFERROR(VLOOKUP(B11,'Runner List'!$B$3:$O$505,6,FALSE),0) -> BANCHAPOL.D | E11: =IFERROR(VLOOKUP(B11,'Runner List'!$B$3:$O$505,7,FALSE),0) -> Male | F11: =IFERROR(VLOOKUP(B11,'Runner List'!$B$3:$O$505,8,FALSE),0) -> 50-59 | G11: =IFERROR(VLOOKUP(B11,'Runner List'!$B$3:$O$505,9,FALSE),0) -> Thai | H11: =IFERROR(VLOOKUP(B11,'Runner List'!$B$3:$O$505,10,FALSE),0) -> MKT33 | I11: =IFERROR(VLOOKUP(B11,'(2)Check In'!$B$4:$I$848,7,FALSE),0) -> 45550.227 | J11: =IFERROR(VLOOKUP(B11,'(2)Check In'!$B$4:$I$848,8,FALSE),0) -> 0.22916667 | K11: =IF(B11="","",IF(K11="",NOW(),K11)) -> 45550.438 | L11: =K11-J11 -> 45550.209 | M11: =COUNTIFS($H$3:H11,H11) -> 8 | N11: =COUNTIFS(F$3:$F11,F11,H$3:$H11,H11,E$3:$E11,E11) -> 1 | O11: =COUNTIFS($F$3:F11,F11,$H$3:H11,H11) -> 1 | S11: LGBTIQAN+ | T11: =COUNTIFS($H$4:$H$198,"MKT33",$E$4:$E$198,"LGBTIQAN+") -> 2 | U11: 20-39 | V11: N/A | X11: LGBTIQAN+ | Y11: =COUNTIFS($H$4:$H$198,"MKT50",$E$4:$E$198,"LGBTIQAN+") -> 1 | Z11: 20-39 | AA11: N/A
A12: 9 | B12: 3389 | C12: =IFERROR(VLOOKUP(B12,'Runner List'!$B$3:$O$505,5,FALSE),0) -> PANUPONG THAWAI | D12: =IFERROR(VLOOKUP(B12,'Runner List'!$B$3:$O$505,6,FALSE),0) -> PANUPONG.T | E12: =IFERROR(VLOOKUP(B12,'Runner List'!$B$3:$O$505,7,FALSE),0) -> Male | F12: =IFERROR(VLOOKUP(B12,'Runner List'!$B$3:$O$505,8,FALSE),0) -> 20-39 | G12: =IFERROR(VLOOKUP(B12,'Runner List'!$B$3:$O$505,9,FALSE),0) -> Thai | H12: =IFERROR(VLOOKUP(B12,'Runner List'!$B$3:$O$505,10,FALSE),0) -> MKT33 | I12: =IFERROR(VLOOKUP(B12,'(2)Check In'!$B$4:$I$848,7,FALSE),0) -> 45550.227 | J12: =IFERROR(VLOOKUP(B12,'(2)Check In'!$B$4:$I$848,8,FALSE),0) -> 0.22916667 | K12: =IF(B12="","",IF(K12="",NOW(),K12)) -> 45550.442 | L12: =K12-J12 -> 45550.213 | M12: =COUNTIFS($H$3:H12,H12) -> 9 | N12: =COUNTIFS(F$3:$F12,F12,H$3:$H12,H12,E$3:$E12,E12) -> 5 | O12: =COUNTIFS($F$3:F12,F12,$H$3:H12,H12) -> 5 | U12: 40-49 | V12: N/A | Z12: 40-49 | AA12: N/A
A13: 10 | B13: 3371 | C13: =IFERROR(VLOOKUP(B13,'Runner List'!$B$3:$O$505,5,FALSE),0) -> CHARUWAT KETSORN | D13: =IFERROR(VLOOKUP(B13,'Runner List'!$B$3:$O$505,6,FALSE),0) -> CHARUWAT.K | E13: =IFERROR(VLOOKUP(B13,'Runner List'!$B$3:$O$505,7,FALSE),0) -> Male | F13: =IFERROR(VLOOKUP(B13,'Runner List'!$B$3:$O$505,8,FALSE),0) -> 50-59 | G13: =IFERROR(VLOOKUP(B13,'Runner List'!$B$3:$O$505,9,FALSE),0) -> Thai | H13: =IFERROR(VLOOKUP(B13,'Runner List'!$B$3:$O$505,10,FALSE),0) -> MKT33 | I13: =IFERROR(VLOOKUP(B13,'(2)Check In'!$B$4:$I$848,7,FALSE),0) -> 45550.229 | J13: =IFERROR(VLOOKUP(B13,'(2)Check In'!$B$4:$I$848,8,FALSE),0) -> 0.22916667 | K13: =IF(B13="","",IF(K13="",NOW(),K13)) -> 45550.446 | L13: =K13-J13 -> 45550.217 | M13: =COUNTIFS($H$3:H13,H13) -> 10 | N13: =COUNTIFS(F$3:$F13,F13,H$3:$H13,H13,E$3:$E13,E13) -> 2 | O13: =COUNTIFS($F$3:F13,F13,$H$3:H13,H13) -> 2 | U13: 50-59 | V13: N/A | Z13: 50-59 | AA13: N/A
A14: 11 | B14: 3348 | C14: =IFERROR(VLOOKUP(B14,'Runner List'!$B$3:$O$505,5,FALSE),0) -> OLIVER HELM | D14: =IFERROR(VLOOKUP(B14,'Runner List'!$B$3:$O$505,6,FALSE),0) -> OLIVER HELM | E14: =IFERROR(VLOOKUP(B14,'Runner List'!$B$3:$O$505,7,FALSE),0) -> Male | F14: =IFERROR(VLOOKUP(B14,'Runner List'!$B$3:$O$505,8,FALSE),0) -> 20-39 | G14: =IFERROR(VLOOKUP(B14,'Runner List'!$B$3:$O$505,9,FALSE),0) -> New Zealand | H14: =IFERROR(VLOOKUP(B14,'Runner List'!$B$3:$O$505,10,FALSE),0) -> MKT33 | I14: =IFERROR(VLOOKUP(B14,'(2)Check In'!$B$4:$I$848,7,FALSE),0) -> 45550.226 | J14: =IFERROR(VLOOKUP(B14,'(2)Check In'!$B$4:$I$848,8,FALSE),0) -> 0.22916667 | K14: =IF(B14="","",IF(K14="",NOW(),K14)) -> 45550.447 | L14: =K14-J14 -> 45550.218 | M14: =COUNTIFS($H$3:H14,H14) -> 11 | N14: =COUNTIFS(F$3:$F14,F14,H$3:$H14,H14,E$3:$E14,E14) -> 6 | O14: =COUNTIFS($F$3:F14,F14,$H$3:H14,H14) -> 6 | U14: 60 Plus | V14: N/A | Z14: 60 Plus | AA14: N/A
A15: 12 | B15: 3370 | C15: =IFERROR(VLOOKUP(B15,'Runner List'!$B$3:$O$505,5,FALSE),0) -> WECHSON KHAMPINIT | D15: =IFERROR(VLOOKUP(B15,'Runner List'!$B$3:$O$505,6,FALSE),0) -> WECHSON.K | E15: =IFERROR(VLOOKUP(B15,'Runner List'!$B$3:$O$505,7,FALSE),0) -> Male | F15: =IFERROR(VLOOKUP(B15,'Runner List'!$B$3:$O$505,8,FALSE),0) -> 60 Plus | G15: =IFERROR(VLOOKUP(B15,'Runner List'!$B$3:$O$505,9,FALSE),0) -> Thai | H15: =IFERROR(VLOOKUP(B15,'Runner List'!$B$3:$O$505,10,FALSE),0) -> MKT33 | I15: =IFERROR(VLOOKUP(B15,'(2)Check In'!$B$4:$I$848,7,FALSE),0) -> 45550.229 | J15: =IFERROR(VLOOKUP(B15,'(2)Check In'!$B$4:$I$848,8,FALSE),0) -> 0.22916667 | K15: =IF(B15="","",IF(K15="",NOW(),K15)) -> 45550.447 | L15: =K15-J15 -> 45550.218 | M15: =COUNTIFS($H$3:H15,H15) -> 12 | N15: =COUNTIFS(F$3:$F15,F15,H$3:$H15,H15,E$3:$E15,E15) -> 1 | O15: =COUNTIFS($F$3:F15,F15,$H$3:H15,H15) -> 1 | T15: =SUM(T4:T14) -> 66 | Y15: =SUM(Y4:Y14) -> 34
A16: 13 | B16: 3386 | C16: =IFERROR(VLOOKUP(B16,'Runner List'!$B$3:$O$505,5,FALSE),0) -> ARTITH KORKIETSOPA | D16: =IFERROR(VLOOKUP(B16,'Runner List'!$B$3:$O$505,6,FALSE),0) -> ARTITH.K | E16: =IFERROR(VLOOKUP(B16,'Runner List'!$B$3:$O$505,7,FALSE),0) -> Male | F16: =IFERROR(VLOOKUP(B16,'Runner List'!$B$3:$O$505,8,FALSE),0) -> 20-39 | G16: =IFERROR(VLOOKUP(B16,'Runner List'!$B$3:$O$505,9,FALSE),0) -> Thai | H16: =IFERROR(VLOOKUP(B16,'Runner List'!$B$3:$O$505,10,FALSE),0) -> MKT33 | I16: =IFERROR(VLOOKUP(B16,'(2)Check In'!$B$4:$I$848,7,FALSE),0) -> 45550.229 | J16: =IFERROR(VLOOKUP(B16,'(2)Check In'!$B$4:$I$848,8,FALSE),0) -> 0.22916667 | K16: =IF(B16="","",IF(K16="",NOW(),K16)) -> 45550.451 | L16: =K16-J16 -> 45550.222 | M16: =COUNTIFS($H$3:H16,H16) -> 13 | N16: =COUNTIFS(F$3:$F16,F16,H$3:$H16,H16,E$3:$E16,E16) -> 7 | O16: =COUNTIFS($F$3:F16,F16,$H$3:H16,H16) -> 7
A17: 14 | B17: 3337 | C17: =IFERROR(VLOOKUP(B17,'Runner List'!$B$3:$O$505,5,FALSE),0) -> CHAIRAT TEEKHASAENEE | D17: =IFERROR(VLOOKUP(B17,'Runner List'!$B$3:$O$505,6,FALSE),0) -> CHAIRAT.T | E17: =IFERROR(VLOOKUP(B17,'Runner List'!$B$3:$O$505,7,FALSE),0) -> Male | F17: =IFERROR(VLOOKUP(B17,'Runner List'!$B$3:$O$505,8,FALSE),0) -> 50-59 | G17: =IFERROR(VLOOKUP(B17,'Runner List'!$B$3:$O$505,9,FALSE),0) -> Thai | H17: =IFERROR(VLOOKUP(B17,'Runner List'!$B$3:$O$505,10,FALSE),0) -> MKT33 | I17: =IFERROR(VLOOKUP(B17,'(2)Check In'!$B$4:$I$848,7,FALSE),0) -> 45550.228 | J17: =IFERROR(VLOOKUP(B17,'(2)Check In'!$B$4:$I$848,8,FALSE),0) -> 0.22916667 | K17: =IF(B17="","",IF(K17="",NOW(),K17)) -> 45550.457 | L17: =K17-J17 -> 45550.228 | M17: =COUNTIFS($H$3:H17,H17) -> 14 | N17: =COUNTIFS(F$3:$F17,F17,H$3:$H17,H17,E$3:$E17,E17) -> 3 | O17: =COUNTIFS($F$3:F17,F17,$H$3:H17,H17) -> 3
A18: 15 | B18: 3316 | C18: =IFERROR(VLOOKUP(B18,'Runner List'!$B$3:$O$505,5,FALSE),0) -> NIPON PATCHARASATID | D18: =IFERROR(VLOOKUP(B18,'Runner List'!$B$3:$O$505,6,FALSE),0) -> NIPON.P | E18: =IFERROR(VLOOKUP(B18,'Runner List'!$B$3:$O$505,7,FALSE),0) -> Male | F18: =IFERROR(VLOOKUP(B18,'Runner List'!$B$3:$O$505,8,FALSE),0) -> 40-49 | G18: =IFERROR(VLOOKUP(B18,'Runner List'!$B$3:$O$505,9,FALSE),0) -> Thai | H18: =IFERROR(VLOOKUP(B18,'Runner List'!$B$3:$O$505,10,FALSE),0) -> MKT33 | I18: =IFERROR(VLOOKUP(B18,'(2)Check In'!$B$4:$I$848,7,FALSE),0) -> 45550.228 | J18: =IFERROR(VLOOKUP(B18,'(2)Check In'!$B$4:$I$848,8,FALSE),0) -> 0.22916667 | K18: =IF(B18="","",IF(K18="",NOW(),K18)) -> 45550.459 | L18: =K18-J18 -> 45550.23 | M18: =COUNTIFS($H$3:H18,H18) -> 15 | N18: =COUNTIFS(F$3:$F18,F18,H$3:$H18,H18,E$3:$E18,E18) -> 4 | O18: =COUNTIFS($F$3:F18,F18,$H$3:H18,H18) -> 4
A19: 16 | B19: 3364 | C19: =IFERROR(VLOOKUP(B19,'Runner List'!$B$3:$O$505,5,FALSE),0) -> EMMANUEL ABADIE | D19: =IFERROR(VLOOKUP(B19,'Runner List'!$B$3:$O$505,6,FALSE),0) -> EMMANUEL.A | E19: =IFERROR(VLOOKUP(B19,'Runner List'!$B$3:$O$505,7,FALSE),0) -> Male | F19: =IFERROR(VLOOKUP(B19,'Runner List'!$B$3:$O$505,8,FALSE),0) -> 20-39 | G19: =IFERROR(VLOOKUP(B19,'Runner List'!$B$3:$O$505,9,FALSE),0) -> French | H19: =IFERROR(VLOOKUP(B19,'Runner List'!$B$3:$O$505,10,FALSE),0) -> MKT33 | I19: =IFERROR(VLOOKUP(B19,'(2)Check In'!$B$4:$I$848,7,FALSE),0) -> 45550.227 | J19: =IFERROR(VLOOKUP(B19,'(2)Check In'!$B$4:$I$848,8,FALSE),0) -> 0.22916667 | K19: =IF(B19="","",IF(K19="",NOW(),K19)) -> 45550.461 | L19: =K19-J19 -> 45550.232 | M19: =COUNTIFS($H$3:H19,H19) -> 16 | N19: =COUNTIFS(F$3:$F19,F19,H$3:$H19,H19,E$3:$E19,E19) -> 8 | O19: =COUNTIFS($F$3:F19,F19,$H$3:H19,H19) -> 8
A20: 17 | B20: 3322 | C20: =IFERROR(VLOOKUP(B20,'Runner List'!$B$3:$O$505,5,FALSE),0) -> TEERAPONG TUMMAPAN | D20: =IFERROR(VLOOKUP(B20,'Runner List'!$B$3:$O$505,6,FALSE),0) -> TEERAPONG.T | E20: =IFERROR(VLOOKUP(B20,'Runner List'!$B$3:$O$505,7,FALSE),0) -> Male | F20: =IFERROR(VLOOKUP(B20,'Runner List'!$B$3:$O$505,8,FALSE),0) -> 20-39 | G20: =IFERROR(VLOOKUP(B20,'Runner List'!$B$3:$O$505,9,FALSE),0) -> Thai | H20: =IFERROR(VLOOKUP(B20,'Runner List'!$B$3:$O$505,10,FALSE),0) -> MKT33 | I20: =IFERROR(VLOOKUP(B20,'(2)Check In'!$B$4:$I$848,7,FALSE),0) -> 45550.228 | J20: =IFERROR(VLOOKUP(B20,'(2)Check In'!$B$4:$I$848,8,FALSE),0) -> 0.22916667 | K20: =IF(B20="","",IF(K20="",NOW(),K20)) -> 45550.462 | L20: =K20-J20 -> 45550.233 | M20: =COUNTIFS($H$3:H20,H20) -> 17 | N20: =COUNTIFS(F$3:$F20,F20,H$3:$H20,H20,E$3:$E20,E20) -> 9 | O20: =COUNTIFS($F$3:F20,F20,$H$3:H20,H20) -> 9
A21: 18 | B21: 3383 | C21: =IFERROR(VLOOKUP(B21,'Runner List'!$B$3:$O$505,5,FALSE),0) -> SARAVUT CHAIBOONRUANG | D21: =IFERROR(VLOOKUP(B21,'Runner List'!$B$3:$O$505,6,FALSE),0) -> SARAVUT.C | E21: =IFERROR(VLOOKUP(B21,'Runner List'!$B$3:$O$505,7,FALSE),0) -> Male | F21: =IFERROR(VLOOKUP(B21,'Runner List'!$B$3:$O$505,8,FALSE),0) -> 40-49 | G21: =IFERROR(VLOOKUP(B21,'Runner List'!$B$3:$O$505,9,FALSE),0) -> Thai | H21: =IFERROR(VLOOKUP(B21,'Runner List'!$B$3:$O$505,10,FALSE),0) -> MKT33 | I21: =IFERROR(VLOOKUP(B21,'(2)Check In'!$B$4:$I$848,7,FALSE),0) -> 45550.227 | J21: =IFERROR(VLOOKUP(B21,'(2)Check In'!$B$4:$I$848,8,FALSE),0) -> 0.22916667 | K21: =IF(B21="","",IF(K21="",NOW(),K21)) -> 45550.463 | L21: =K21-J21 -> 45550.234 | M21: =COUNTIFS($H$3:H21,H21) -> 18 | N21: =COUNTIFS(F$3:$F21,F21,H$3:$H21,H21,E$3:$E21,E21) -> 5 | O21: =COUNTIFS($F$3:F21,F21,$H$3:H21,H21) -> 5
A22: 19 | B22: 3369 | C22: =IFERROR(VLOOKUP(B22,'Runner List'!$B$3:$O$505,5,FALSE),0) -> SURASAK CHUNTAPA | D22: =IFERROR(VLOOKUP(B22,'Runner List'!$B$3:$O$505,6,FALSE),0) -> SURASAK.C | E22: =IFERROR(VLOOKUP(B22,'Runner List'!$B$3:$O$505,7,FALSE),0) -> Male | F22: =IFERROR(VLOOKUP(B22,'Runner List'!$B$3:$O$505,8,FALSE),0) -> 20-39 | G22: =IFERROR(VLOOKUP(B22,'Runner List'!$B$3:$O$505,9,FALSE),0) -> Thai | H22: =IFERROR(VLOOKUP(B22,'Runner List'!$B$3:$O$505,10,FALSE),0) -> MKT33 | I22: =IFERROR(VLOOKUP(B22,'(2)Check In'!$B$4:$I$848,7,FALSE),0) -> 45550.227 | J22: =IFERROR(VLOOKUP(B22,'(2)Check In'!$B$4:$I$848,8,FALSE),0) -> 0.22916667 | K22: =IF(B22="","",IF(K22="",NOW(),K22)) -> 45550.463 | L22: =K22-J22 -> 45550.234 | M22: =COUNTIFS($H$3:H22,H22) -> 19 | N22: =COUNTIFS(F$3:$F22,F22,H$3:$H22,H22,E$3:$E22,E22) -> 10 | O22: =COUNTIFS($F$3:F22,F22,$H$3:H22,H22) -> 10
A23: 20 | B23: 3390 | C23: =IFERROR(VLOOKUP(B23,'Runner List'!$B$3:$O$505,5,FALSE),0) -> URAIWAN JINAPHO | D23: =IFERROR(VLOOKUP(B23,'Runner List'!$B$3:$O$505,6,FALSE),0) -> URAIWAN.J | E23: =IFERROR(VLOOKUP(B23,'Runner List'!$B$3:$O$505,7,FALSE),0) -> Female | F23: =IFERROR(VLOOKUP(B23,'Runner List'!$B$3:$O$505,8,FALSE),0) -> 20-39 | G23: =IFERROR(VLOOKUP(B23,'Runner List'!$B$3:$O$505,9,FALSE),0) -> Thai | H23: =IFERROR(VLOOKUP(B23,'Runner List'!$B$3:$O$505,10,FALSE),0) -> MKT33 | I23: =IFERROR(VLOOKUP(B23,'(2)Check In'!$B$4:$I$848,7,FALSE),0) -> 45550.226 | J23: =IFERROR(VLOOKUP(B23,'(2)Check In'!$B$4:$I$848,8,FALSE),0) -> 0.22916667 | K23: =IF(B23="","",IF(K23="",NOW(),K23)) -> 45550.469 | L23: =K23-J23 -> 45550.24 | M23: =COUNTIFS($H$3:H23,H23) -> 20 | N23: =COUNTIFS(F$3:$F23,F23,H$3:$H23,H23,E$3:$E23,E23) -> 1 | O23: =COUNTIFS($F$3:F23,F23,$H$3:H23,H23) -> 11
A24: 21 | B24: 3353 | C24: =IFERROR(VLOOKUP(B24,'Runner List'!$B$3:$O$505,5,FALSE),0) -> MANOO SUKTHANG | D24: =IFERROR(VLOOKUP(B24,'Runner List'!$B$3:$O$505,6,FALSE),0) -> MANOO.S | E24: =IFERROR(VLOOKUP(B24,'Runner List'!$B$3:$O$505,7,FALSE),0) -> Male | F24: =IFERROR(VLOOKUP(B24,'Runner List'!$B$3:$O$505,8,FALSE),0) -> 40-49 | G24: =IFERROR(VLOOKUP(B24,'Runner List'!$B$3:$O$505,9,FALSE),0) -> Thai | H24: =IFERROR(VLOOKUP(B24,'Runner List'!$B$3:$O$505,10,FALSE),0) -> MKT33 | I24: =IFERROR(VLOOKUP(B24,'(2)Check In'!$B$4:$I$848,7,FALSE),0) -> 45550.227 | J24: =IFERROR(VLOOKUP(B24,'(2)Check In'!$B$4:$I$848,8,FALSE),0) -> 0.22916667 | K24: =IF(B24="","",IF(K24="",NOW(),K24)) -> 45550.471 | L24: =K24-J24 -> 45550.242 | M24: =COUNTIFS($H$3:H24,H24) -> 21 | N24: =COUNTIFS(F$3:$F24,F24,H$3:$H24,H24,E$3:$E24,E24) -> 6 | O24: =COUNTIFS($F$3:F24,F24,$H$3:H24,H24) -> 6
A25: 22 | B25: 3382 | C25: =IFERROR(VLOOKUP(B25,'Runner List'!$B$3:$O$505,5,FALSE),0) -> KHATTIYA HOMTHONG | D25: =IFERROR(VLOOKUP(B25,'Runner List'!$B$3:$O$505,6,FALSE),0) -> KHATTIYA.H | E25: =IFERROR(VLOOKUP(B25,'Runner List'!$B$3:$O$505,7,FALSE),0) -> Female | F25: =IFERROR(VLOOKUP(B25,'Runner List'!$B$3:$O$505,8,FALSE),0) -> 20-39 | G25: =IFERROR(VLOOKUP(B25,'Runner List'!$B$3:$O$505,9,FALSE),0) -> Thai | H25: =IFERROR(VLOOKUP(B25,'Runner List'!$B$3:$O$505,10,FALSE),0) -> MKT33 | I25: =IFERROR(VLOOKUP(B25,'(2)Check In'!$B$4:$I$848,7,FALSE),0) -> 45550.227 | J25: =IFERROR(VLOOKUP(B25,'(2)Check In'!$B$4:$I$848,8,FALSE),0) -> 0.22916667 | K25: =IF(B25="","",IF(K25="",NOW(),K25)) -> 45550.473 | L25: =K25-J25 -> 45550.244 | M25: =COUNTIFS($H$3:H25,H25) -> 22 | N25: =COUNTIFS(F$3:$F25,F25,H$3:$H25,H25,E$3:$E25,E25) -> 2 | O25: =COUNTIFS($F$3:F25,F25,$H$3:H25,H25) -> 12
A26: 23 | B26: 3385 | C26: =IFERROR(VLOOKUP(B26,'Runner List'!$B$3:$O$505,5,FALSE),0) -> UDOM YAVILAS | D26: =IFERROR(VLOOKUP(B26,'Runner List'!$B$3:$O$505,6,FALSE),0) -> UDOM.Y | E26: =IFERROR(VLOOKUP(B26,'Runner List'!$B$3:$O$505,7,FALSE),0) -> Male | F26: =IFERROR(VLOOKUP(B26,'Runner List'!$B$3:$O$505,8,FALSE),0) -> 50-59 | G26: =IFERROR(VLOOKUP(B26,'Runner List'!$B$3:$O$505,9,FALSE),0) -> Thai | H26: =IFERROR(VLOOKUP(B26,'Runner List'!$B$3:$O$505,10,FALSE),0) -> MKT33 | I26: =IFERROR(VLOOKUP(B26,'(2)Check In'!$B$4:$I$848,7,FALSE),0) -> 45550.229 | J26: =IFERROR(VLOOKUP(B26,'(2)Check In'!$B$4:$I$848,8,FALSE),0) -> 0.22916667 | K26: =IF(B26="","",IF(K26="",NOW(),K26)) -> 45550.474 | L26: =K26-J26 -> 45550.245 | M26: =COUNTIFS($H$3:H26,H26) -> 23 | N26: =COUNTIFS(F$3:$F26,F26,H$3:$H26,H26,E$3:$E26,E26) -> 4 | O26: =COUNTIFS($F$3:F26,F26,$H$3:H26,H26) -> 4
A27: 24 | B27: 3384 | C27: =IFERROR(VLOOKUP(B27,'Runner List'!$B$3:$O$505,5,FALSE),0) -> SOPHA USUMANI | D27: =IFERROR(VLOOKUP(B27,'Runner List'!$B$3:$O$505,6,FALSE),0) -> SOPHA.U | E27: =IFERROR(VLOOKUP(B27,'Runner List'!$B$3:$O$505,7,FALSE),0) -> Female | F27: =IFERROR(VLOOKUP(B27,'Runner List'!$B$3:$O$505,8,FALSE),0) -> 40-49 | G27: =IFERROR(VLOOKUP(B27,'Runner List'!$B$3:$O$505,9,FALSE),0) -> Thai | H27: =IFERROR(VLOOKUP(B27,'Runner List'!$B$3:$O$505,10,FALSE),0) -> MKT33 | I27: =IFERROR(VLOOKUP(B27,'(2)Check In'!$B$4:$I$848,7,FALSE),0) -> 45550.228 | J27: =IFERROR(VLOOKUP(B27,'(2)Check In'!$B$4:$I$848,8,FALSE),0) -> 0.22916667 | K27: =IF(B27="","",IF(K27="",NOW(),K27)) -> 45550.474 | L27: =K27-J27 -> 45550.245 | M27: =COUNTIFS($H$3:H27,H27) -> 24 | N27: =COUNTIFS(F$3:$F27,F27,H$3:$H27,H27,E$3:$E27,E27) -> 1 | O27: =COUNTIFS($F$3:F27,F27,$H$3:H27,H27) -> 7
... A59: 56 | B59: 3366 | C59: =IFERROR(VLOOKUP(B59,'Runner List'!$B$3:$O$505,5,FALSE),0) -> SUPAROEK NIYOMKARN | D59: =IFERROR(VLOOKUP(B59,'Runner List'!$B$3:$O$505,6,FALSE),0) -> SUPAROEK.N | E59: =IFERROR(VLOOKUP(B59,'Runner List'!$B$3:$O$505,7,FALSE),0) -> Male | F59: =IFERROR(VLOOKUP(B59,'Runner List'!$B$3:$O$505,8,FALSE),0) -> 20-39 | G59: =IFERROR(VLOOKUP(B59,'Runner List'!$B$3:$O$505,9,FALSE),0) -> Thai | H59: =IFERROR(VLOOKUP(B59,'Runner List'!$B$3:$O$505,10,FALSE),0) -> MKT33 | I59: =IFERROR(VLOOKUP(B59,'(2)Check In'!$B$4:$I$848,7,FALSE),0) -> 45550.229 | J59: =IFERROR(VLOOKUP(B59,'(2)Check In'!$B$4:$I$848,8,FALSE),0) -> 0.22916667 | K59: =IF(B59="","",IF(K59="",NOW(),K59)) -> 45550.576 | L59: =K59-J59 -> 45550.347 | M59: =COUNTIFS($H$3:H59,H59) -> 51 | N59: =COUNTIFS(F$3:$F59,F59,H$3:$H59,H59,E$3:$E59,E59) -> 16 | O59: =COUNTIFS($F$3:F59,F59,$H$3:H59,H59) -> 27
A60: 57 | B60: 3376 | C60: =IFERROR(VLOOKUP(B60,'Runner List'!$B$3:$O$505,5,FALSE),0) -> THUNYALUK BOONPONG | D60: =IFERROR(VLOOKUP(B60,'Runner List'!$B$3:$O$505,6,FALSE),0) -> THUNYALUK.B | E60: =IFERROR(VLOOKUP(B60,'Runner List'!$B$3:$O$505,7,FALSE),0) -> Female | F60: =IFERROR(VLOOKUP(B60,'Runner List'!$B$3:$O$505,8,FALSE),0) -> 20-39 | G60: =IFERROR(VLOOKUP(B60,'Runner List'!$B$3:$O$505,9,FALSE),0) -> Thai | H60: =IFERROR(VLOOKUP(B60,'Runner List'!$B$3:$O$505,10,FALSE),0) -> MKT33 | I60: =IFERROR(VLOOKUP(B60,'(2)Check In'!$B$4:$I$848,7,FALSE),0) -> 45550.227 | J60: =IFERROR(VLOOKUP(B60,'(2)Check In'!$B$4:$I$848,8,FALSE),0) -> 0.22916667 | K60: =IF(B60="","",IF(K60="",NOW(),K60)) -> 45550.577 | L60: =K60-J60 -> 45550.347 | M60: =COUNTIFS($H$3:H60,H60) -> 52 | N60: =COUNTIFS(F$3:$F60,F60,H$3:$H60,H60,E$3:$E60,E60) -> 11 | O60: =COUNTIFS($F$3:F60,F60,$H$3:H60,H60) -> 28 | P60: Cut off
A61: 58 | B61: 3374 | C61: =IFERROR(VLOOKUP(B61,'Runner List'!$B$3:$O$505,5,FALSE),0) -> JULARRUCK LOMPAIBOON | D61: =IFERROR(VLOOKUP(B61,'Runner List'!$B$3:$O$505,6,FALSE),0) -> JULARRUCK.L | E61: =IFERROR(VLOOKUP(B61,'Runner List'!$B$3:$O$505,7,FALSE),0) -> Female | F61: =IFERROR(VLOOKUP(B61,'Runner List'!$B$3:$O$505,8,FALSE),0) -> 60 Plus | G61: =IFERROR(VLOOKUP(B61,'Runner List'!$B$3:$O$505,9,FALSE),0) -> Thai | H61: =IFERROR(VLOOKUP(B61,'Runner List'!$B$3:$O$505,10,FALSE),0) -> MKT33 | I61: =IFERROR(VLOOKUP(B61,'(2)Check In'!$B$4:$I$848,7,FALSE),0) -> 45550.226 | J61: =IFERROR(VLOOKUP(B61,'(2)Check In'!$B$4:$I$848,8,FALSE),0) -> 0.22916667 | K61: =IF(B61="","",IF(K61="",NOW(),K61)) -> 45550.579 | L61: =K61-J61 -> 45550.35 | M61: =COUNTIFS($H$3:H61,H61) -> 53 | N61: =COUNTIFS(F$3:$F61,F61,H$3:$H61,H61,E$3:$E61,E61) -> 1 | O61: =COUNTIFS($F$3:F61,F61,$H$3:H61,H61) -> 3
A62: 59 | B62: 3356 | C62: =IFERROR(VLOOKUP(B62,'Runner List'!$B$3:$O$505,5,FALSE),0) -> MATCHA PHORIN | D62: =IFERROR(VLOOKUP(B62,'Runner List'!$B$3:$O$505,6,FALSE),0) -> MATCHA.P | E62: =IFERROR(VLOOKUP(B62,'Runner List'!$B$3:$O$505,7,FALSE),0) -> LGBTIQAN+ | F62: =IFERROR(VLOOKUP(B62,'Runner List'!$B$3:$O$505,8,FALSE),0) -> 40-49 | G62: =IFERROR(VLOOKUP(B62,'Runner List'!$B$3:$O$505,9,FALSE),0) -> Thai | H62: =IFERROR(VLOOKUP(B62,'Runner List'!$B$3:$O$505,10,FALSE),0) -> MKT33 | I62: =IFERROR(VLOOKUP(B62,'(2)Check In'!$B$4:$I$848,7,FALSE),0) -> 45550.229 | J62: =IFERROR(VLOOKUP(B62,'(2)Check In'!$B$4:$I$848,8,FALSE),0) -> 0.22916667 | K62: =IF(B62="","",IF(K62="",NOW(),K62)) -> 45550.581 | L62: =K62-J62 -> 45550.352 | M62: =COUNTIFS($H$3:H62,H62) -> 54 | N62: =COUNTIFS(H$3:$H62,H62,E$3:$E62,E62) -> 2 | O62: =COUNTIFS($F$3:F62,F62,$H$3:H62,H62) -> 13
A63: 60 | B63: 3349 | C63: =IFERROR(VLOOKUP(B63,'Runner List'!$B$3:$O$505,5,FALSE),0) -> ANUCHIT BOONSIRI | D63: =IFERROR(VLOOKUP(B63,'Runner List'!$B$3:$O$505,6,FALSE),0) -> ANUCHIT.B | E63: =IFERROR(VLOOKUP(B63,'Runner List'!$B$3:$O$505,7,FALSE),0) -> Male | F63: =IFERROR(VLOOKUP(B63,'Runner List'!$B$3:$O$505,8,FALSE),0) -> 50-59 | G63: =IFERROR(VLOOKUP(B63,'Runner List'!$B$3:$O$505,9,FALSE),0) -> Thai | H63: =IFERROR(VLOOKUP(B63,'Runner List'!$B$3:$O$505,10,FALSE),0) -> MKT33 | I63: =IFERROR(VLOOKUP(B63,'(2)Check In'!$B$4:$I$848,7,FALSE),0) -> 45550.227 | J63: =IFERROR(VLOOKUP(B63,'(2)Check In'!$B$4:$I$848,8,FALSE),0) -> 0.22916667 | K63: =IF(B63="","",IF(K63="",NOW(),K63)) -> 45550.583 | L63: =K63-J63 -> 45550.354 | M63: =COUNTIFS($H$3:H63,H63) -> 55 | N63: =COUNTIFS(F$3:$F63,F63,H$3:$H63,H63,E$3:$E63,E63) -> 10 | O63: =COUNTIFS($F$3:F63,F63,$H$3:H63,H63) -> 11
A64: 61 | B64: 5047 | C64: =IFERROR(VLOOKUP(B64,'Runner List'!$B$3:$O$505,5,FALSE),0) -> TAWATCHAI LATHIANG | D64: =IFERROR(VLOOKUP(B64,'Runner List'!$B$3:$O$505,6,FALSE),0) -> TAWATCHAI LATHIANG | E64: =IFERROR(VLOOKUP(B64,'Runner List'!$B$3:$O$505,7,FALSE),0) -> Male | F64: =IFERROR(VLOOKUP(B64,'Runner List'!$B$3:$O$505,8,FALSE),0) -> 20-39 | G64: =IFERROR(VLOOKUP(B64,'Runner List'!$B$3:$O$505,9,FALSE),0) -> Thai | H64: =IFERROR(VLOOKUP(B64,'Runner List'!$B$3:$O$505,10,FALSE),0) -> MKT50 | I64: =IFERROR(VLOOKUP(B64,'(2)Check In'!$B$4:$I$848,7,FALSE),0) -> 45550.204 | J64: =IFERROR(VLOOKUP(B64,'(2)Check In'!$B$4:$I$848,8,FALSE),0) -> 0.20833333 | K64: =IF(B64="","",IF(K64="",NOW(),K64)) -> 45550.584 | L64: =K64-J64 -> 45550.376 | M64: =COUNTIFS($H$3:H64,H64) -> 6 | N64: =COUNTIFS(F$3:$F64,F64,H$3:$H64,H64,E$3:$E64,E64) -> 1 | O64: =COUNTIFS($F$3:F64,F64,$H$3:H64,H64) -> 1
A65: 62 | B65: 3351 | C65: =IFERROR(VLOOKUP(B65,'Runner List'!$B$3:$O$505,5,FALSE),0) -> CHRISTIAN WENDELL | D65: =IFERROR(VLOOKUP(B65,'Runner List'!$B$3:$O$505,6,FALSE),0) -> CHRISTIAN.W | E65: =IFERROR(VLOOKUP(B65,'Runner List'!$B$3:$O$505,7,FALSE),0) -> Male | F65: =IFERROR(VLOOKUP(B65,'Runner List'!$B$3:$O$505,8,FALSE),0) -> 40-49 | G65: =IFERROR(VLOOKUP(B65,'Runner List'!$B$3:$O$505,9,FALSE),0) -> Philippines | H65: =IFERROR(VLOOKUP(B65,'Runner List'!$B$3:$O$505,10,FALSE),0) -> MKT33 | I65: =IFERROR(VLOOKUP(B65,'(2)Check In'!$B$4:$I$848,7,FALSE),0) -> 45550.227 | J65: =IFERROR(VLOOKUP(B65,'(2)Check In'!$B$4:$I$848,8,FALSE),0) -> 0.22916667 | K65: =IF(B65="","",IF(K65="",NOW(),K65)) -> 45550.59 | L65: =K65-J65 -> 45550.361 | M65: =COUNTIFS($H$3:H65,H65) -> 56 | N65: =COUNTIFS(F$3:$F65,F65,H$3:$H65,H65,E$3:$E65,E65) -> 10 | O65: =COUNTIFS($F$3:F65,F65,$H$3:H65,H65) -> 14
A66: 63 | B66: 5040 | C66: =IFERROR(VLOOKUP(B66,'Runner List'!$B$3:$O$505,5,FALSE),0) -> ROBERT MCCONNON | D66: =IFERROR(VLOOKUP(B66,'Runner List'!$B$3:$O$505,6,FALSE),0) -> ROBERT.M | E66: =IFERROR(VLOOKUP(B66,'Runner List'!$B$3:$O$505,7,FALSE),0) -> Male | F66: =IFERROR(VLOOKUP(B66,'Runner List'!$B$3:$O$505,8,FALSE),0) -> 40-49 | G66: =IFERROR(VLOOKUP(B66,'Runner List'!$B$3:$O$505,9,FALSE),0) -> Australia | H66: =IFERROR(VLOOKUP(B66,'Runner List'!$B$3:$O$505,10,FALSE),0) -> MKT50 | I66: =IFERROR(VLOOKUP(B66,'(2)Check In'!$B$4:$I$848,7,FALSE),0) -> 45550.204 | J66: =IFERROR(VLOOKUP(B66,'(2)Check In'!$B$4:$I$848,8,FALSE),0) -> 0.20833333 | K66: =IF(B66="","",IF(K66="",NOW(),K66)) -> 45550.592 | L66: =K66-J66 -> 45550.384 | M66: =COUNTIFS($H$3:H66,H66) -> 7 | N66: =COUNTIFS(F$3:$F66,F66,H$3:$H66,H66,E$3:$E66,E66) -> 4 | O66: =COUNTIFS($F$3:F66,F66,$H$3:H66,H66) -> 4
A67: 64 | B67: 3338 | C67: =IFERROR(VLOOKUP(B67,'Runner List'!$B$3:$O$505,5,FALSE),0) -> PANUWAT BUAYOY | D67: =IFERROR(VLOOKUP(B67,'Runner List'!$B$3:$O$505,6,FALSE),0) -> PANUWAT.B | E67: =IFERROR(VLOOKUP(B67,'Runner List'!$B$3:$O$505,7,FALSE),0) -> Male | F67: =IFERROR(VLOOKUP(B67,'Runner List'!$B$3:$O$505,8,FALSE),0) -> 20-39 | G67: =IFERROR(VLOOKUP(B67,'Runner List'!$B$3:$O$505,9,FALSE),0) -> Thai | H67: =IFERROR(VLOOKUP(B67,'Runner List'!$B$3:$O$505,10,FALSE),0) -> MKT33 | I67: =IFERROR(VLOOKUP(B67,'(2)Check In'!$B$4:$I$848,7,FALSE),0) -> 45550.227 | J67: =IFERROR(VLOOKUP(B67,'(2)Check In'!$B$4:$I$848,8,FALSE),0) -> 0.22916667 | K67: =IF(B67="","",IF(K67="",NOW(),K67)) -> 45550.601 | L67: =K67-J67 -> 45550.372 | M67: =COUNTIFS($H$3:H67,H67) -> 57 | N67: =COUNTIFS(F$3:$F67,F67,H$3:$H67,H67,E$3:$E67,E67) -> 17 | O67: =COUNTIFS($F$3:F67,F67,$H$3:H67,H67) -> 29
A68: 65 | B68: 3326 | C68: =IFERROR(VLOOKUP(B68,'Runner List'!$B$3:$O$505,5,FALSE),0) -> JANTHIMA CHOTISTHAYANGURA | D68: =IFERROR(VLOOKUP(B68,'Runner List'!$B$3:$O$505,6,FALSE),0) -> JANTHIMA.C | E68: =IFERROR(VLOOKUP(B68,'Runner List'!$B$3:$O$505,7,FALSE),0) -> Female | F68: =IFERROR(VLOOKUP(B68,'Runner List'!$B$3:$O$505,8,FALSE),0) -> 50-59 | G68: =IFERROR(VLOOKUP(B68,'Runner List'!$B$3:$O$505,9,FALSE),0) -> Thai | H68: =IFERROR(VLOOKUP(B68,'Runner List'!$B$3:$O$505,10,FALSE),0) -> MKT33 | I68: =IFERROR(VLOOKUP(B68,'(2)Check In'!$B$4:$I$848,7,FALSE),0) -> 45550.227 | J68: =IFERROR(VLOOKUP(B68,'(2)Check In'!$B$4:$I$848,8,FALSE),0) -> 0.22916667 | K68: =IF(B68="","",IF(K68="",NOW(),K68)) -> 45550.604 | L68: =K68-J68 -> 45550.375 | M68: =COUNTIFS($H$3:H68,H68) -> 58 | N68: =COUNTIFS(F$3:$F68,F68,H$3:$H68,H68,E$3:$E68,E68) -> 2 | O68: =COUNTIFS($F$3:F68,F68,$H$3:H68,H68) -> 12
A69: 66 | B69: 3325 | C69: =IFERROR(VLOOKUP(B69,'Runner List'!$B$3:$O$505,5,FALSE),0) -> DARANEE CHOTISTHAYANGURA | D69: =IFERROR(VLOOKUP(B69,'Runner List'!$B$3:$O$505,6,FALSE),0) -> DARANEE.C | E69: =IFERROR(VLOOKUP(B69,'Runner List'!$B$3:$O$505,7,FALSE),0) -> Female | F69: =IFERROR(VLOOKUP(B69,'Runner List'!$B$3:$O$505,8,FALSE),0) -> 50-59 | G69: =IFERROR(VLOOKUP(B69,'Runner List'!$B$3:$O$505,9,FALSE),0) -> Thai | H69: =IFERROR(VLOOKUP(B69,'Runner List'!$B$3:$O$505,10,FALSE),0) -> MKT33 | I69: =IFERROR(VLOOKUP(B69,'(2)Check In'!$B$4:$I$848,7,FALSE),0) -> 45550.227 | J69: =IFERROR(VLOOKUP(B69,'(2)Check In'!$B$4:$I$848,8,FALSE),0) -> 0.22916667 | K69: =IF(B69="","",IF(K69="",NOW(),K69)) -> 45550.604 | L69: =K69-J69 -> 45550.375 | M69: =COUNTIFS($H$3:H69,H69) -> 59 | N69: =COUNTIFS(F$3:$F69,F69,H$3:$H69,H69,E$3:$E69,E69) -> 3 | O69: =COUNTIFS($F$3:F69,F69,$H$3:H69,H69) -> 13
A70: 67 | B70: 3332 | C70: =IFERROR(VLOOKUP(B70,'Runner List'!$B$3:$O$505,5,FALSE),0) -> NIPAWAN JAITANONG | D70: =IFERROR(VLOOKUP(B70,'Runner List'!$B$3:$O$505,6,FALSE),0) -> NIPAWAN.J | E70: =IFERROR(VLOOKUP(B70,'Runner List'!$B$3:$O$505,7,FALSE),0) -> Female | F70: =IFERROR(VLOOKUP(B70,'Runner List'!$B$3:$O$505,8,FALSE),0) -> 40-49 | G70: =IFERROR(VLOOKUP(B70,'Runner List'!$B$3:$O$505,9,FALSE),0) -> Thai | H70: =IFERROR(VLOOKUP(B70,'Runner List'!$B$3:$O$505,10,FALSE),0) -> MKT33 | I70: =IFERROR(VLOOKUP(B70,'(2)Check In'!$B$4:$I$848,7,FALSE),0) -> 45550.231 | J70: =IFERROR(VLOOKUP(B70,'(2)Check In'!$B$4:$I$848,8,FALSE),0) -> 0.22916667 | K70: =IF(B70="","",IF(K70="",NOW(),K70)) -> 45550.608 | L70: =K70-J70 -> 45550.379 | M70: =COUNTIFS($H$3:H70,H70) -> 60 | N70: =COUNTIFS(F$3:$F70,F70,H$3:$H70,H70,E$3:$E70,E70) -> 4 | O70: =COUNTIFS($F$3:F70,F70,$H$3:H70,H70) -> 15
A71: 68 | B71: 3328 | C71: =IFERROR(VLOOKUP(B71,'Runner List'!$B$3:$O$505,5,FALSE),0) -> PHAWINEE TIPHAWANG | D71: =IFERROR(VLOOKUP(B71,'Runner List'!$B$3:$O$505,6,FALSE),0) -> PHAWINEE.T | E71: =IFERROR(VLOOKUP(B71,'Runner List'!$B$3:$O$505,7,FALSE),0) -> Female | F71: =IFERROR(VLOOKUP(B71,'Runner List'!$B$3:$O$505,8,FALSE),0) -> 20-39 | G71: =IFERROR(VLOOKUP(B71,'Runner List'!$B$3:$O$505,9,FALSE),0) -> Thai | H71: =IFERROR(VLOOKUP(B71,'Runner List'!$B$3:$O$505,10,FALSE),0) -> MKT33 | I71: =IFERROR(VLOOKUP(B71,'(2)Check In'!$B$4:$I$848,7,FALSE),0) -> 45550.231 | J71: =IFERROR(VLOOKUP(B71,'(2)Check In'!$B$4:$I$848,8,FALSE),0) -> 0.22916667 | K71: =IF(B71="","",IF(K71="",NOW(),K71)) -> 45550.608 | L71: =K71-J71 -> 45550.379 | M71: =COUNTIFS($H$3:H71,H71) -> 61 | N71: =COUNTIFS(F$3:$F71,F71,H$3:$H71,H71,E$3:$E71,E71) -> 12 | O71: =COUNTIFS($F$3:F71,F71,$H$3:H71,H71) -> 30
...

Sheet (2)Check In
A1: CHECK IN RUNNER "Mae Khanin Trail 2024" | M1: Check In Runner
A2: No. | B2: BIB Number | C2: Name Surname | D2: Gender | E2: Age Group | F2: Nationality | G2: Race | H2: Check in Time | I2: Start Time
A3: ลำดับ | B3: หมายเลขแข่งขัน | C3: ชื่อ-นามสกุล | D3: เพศ | E3: กลุ่มอายุ | F3: สัญชาติ | G3: ระยะแข่งขัน | H3: รายงานตัว ณ จุดปล่อยตัว | I3: เวลาปล่อยตัว | M3: MKT33 | N3: =COUNTIF($G$4:$G$200,"MKT33") -> 74 | R3: MKT50 | S3: =COUNTIF($G$4:$G$200,"MKT50") -> 35
A4: 1 | B4: 5026 | C4: =IFERROR(VLOOKUP(B4,'Runner List'!$B$3:$OT$505,5,FALSE),0) -> MALILA KOSURA | D4: =IFERROR(VLOOKUP(B4,'Runner List'!$B$3:$O$505,7,FALSE),0) -> Female | E4: =IFERROR(VLOOKUP(B4,'Runner List'!$B$3:$O$505,8,FALSE),0) -> 50-59 | F4: =IFERROR(VLOOKUP(B4,'Runner List'!$B$3:$O$505,9,FALSE),0) -> Thai | G4: =IFERROR(VLOOKUP(B4,'Runner List'!$B$3:$O$505,10,FALSE),0) -> MKT50 | H4: =IF(B4="","",IF(H4="",NOW(),H4)) -> 45550.204 | I4: =IFERROR(VLOOKUP(B4,'Runner List'!$B$3:$O$505,12,FALSE),0) -> 0.20833333 | M4: Male | N4: =COUNTIFS($G$4:$G$200,"MKT33",$D$4:$D$200,"Male") -> 47 | O4: 20-39 | P4: =COUNTIFS($G$4:$G$200,"MKT33",$D$4:$D$200,"Male",$E$4:$E$200,"20-39") -> 19 | R4: Male | S4: =COUNTIFS($G$4:$G$200,"MKT50",$D$4:$D$200,"Male") -> 25 | T4: 20-39 | U4: =COUNTIFS($G$4:$G$200,"MKT50",$D$4:$D$200,"Male",$E$4:$E$200,"20-39") -> 3
A5: 2 | B5: 5016 | C5: =IFERROR(VLOOKUP(B5,'Runner List'!$B$3:$OT$505,5,FALSE),0) -> NARUDAPA WATTANATEERAPAK | D5: =IFERROR(VLOOKUP(B5,'Runner List'!$B$3:$O$505,7,FALSE),0) -> Female | E5: =IFERROR(VLOOKUP(B5,'Runner List'!$B$3:$O$505,8,FALSE),0) -> 40-49 | F5: =IFERROR(VLOOKUP(B5,'Runner List'!$B$3:$O$505,9,FALSE),0) -> Thai | G5: =IFERROR(VLOOKUP(B5,'Runner List'!$B$3:$O$505,10,FALSE),0) -> MKT50 | H5: =IF(B5="","",IF(H5="",NOW(),H5)) -> 45550.204 | I5: =IFERROR(VLOOKUP(B5,'Runner List'!$B$3:$O$505,12,FALSE),0) -> 0.20833333 | O5: 40-49 | P5: =COUNTIFS($G$4:$G$200,"MKT33",$D$4:$D$200,"Male",$E$4:$E$200,"40-49") -> 15 | T5: 40-49 | U5: =COUNTIFS($G$4:$G$200,"MKT50",$D$4:$D$200,"Male",$E$4:$E$200,"40-49") -> 14
A6: 3 | B6: 5018 | C6: =IFERROR(VLOOKUP(B6,'Runner List'!$B$3:$OT$505,5,FALSE),0) -> MANOP MAEJIT | D6: =IFERROR(VLOOKUP(B6,'Runner List'!$B$3:$O$505,7,FALSE),0) -> Male | E6: =IFERROR(VLOOKUP(B6,'Runner List'!$B$3:$O$505,8,FALSE),0) -> 40-49 | F6: =IFERROR(VLOOKUP(B6,'Runner List'!$B$3:$O$505,9,FALSE),0) -> Thai | G6: =IFERROR(VLOOKUP(B6,'Runner List'!$B$3:$O$505,10,FALSE),0) -> MKT50 | H6: =IF(B6="","",IF(H6="",NOW(),H6)) -> 45550.204 | I6: =IFERROR(VLOOKUP(B6,'Runner List'!$B$3:$O$505,12,FALSE),0) -> 0.20833333 | O6: 50-59 | P6: =COUNTIFS($G$4:$G$200,"MKT33",$D$4:$D$200,"Male",$E$4:$E$200,"50-59") -> 11 | T6: 50-59 | U6: =COUNTIFS($G$4:$G$200,"MKT50",$D$4:$D$200,"Male",$E$4:$E$200,"50-59") -> 5
A7: 4 | B7: 5040 | C7: =IFERROR(VLOOKUP(B7,'Runner List'!$B$3:$OT$505,5,FALSE),0) -> ROBERT MCCONNON | D7: =IFERROR(VLOOKUP(B7,'Runner List'!$B$3:$O$505,7,FALSE),0) -> Male | E7: =IFERROR(VLOOKUP(B7,'Runner List'!$B$3:$O$505,8,FALSE),0) -> 40-49 | F7: =IFERROR(VLOOKUP(B7,'Runner List'!$B$3:$O$505,9,FALSE),0) -> Australia | G7: =IFERROR(VLOOKUP(B7,'Runner List'!$B$3:$O$505,10,FALSE),0) -> MKT50 | H7: =IF(B7="","",IF(H7="",NOW(),H7)) -> 45550.204 | I7: =IFERROR(VLOOKUP(B7,'Runner List'!$B$3:$O$505,12,FALSE),0) -> 0.20833333 | O7: 60 Plus | P7: =COUNTIFS($G$4:$G$200,"MKT33",$D$4:$D$200,"Male",$E$4:$E$200,"60 Plush") -> 0 | T7: 60 Plus | U7: =COUNTIFS($G$4:$G$200,"MKT50",$D$4:$D$200,"Male",$E$4:$E$200,"60 Plus") -> 3
A8: 5 | B8: 5047 | C8: =IFERROR(VLOOKUP(B8,'Runner List'!$B$3:$OT$505,5,FALSE),0) -> TAWATCHAI LATHIANG | D8: =IFERROR(VLOOKUP(B8,'Runner List'!$B$3:$O$505,7,FALSE),0) -> Male | E8: =IFERROR(VLOOKUP(B8,'Runner List'!$B$3:$O$505,8,FALSE),0) -> 20-39 | F8: =IFERROR(VLOOKUP(B8,'Runner List'!$B$3:$O$505,9,FALSE),0) -> Thai | G8: =IFERROR(VLOOKUP(B8,'Runner List'!$B$3:$O$505,10,FALSE),0) -> MKT50 | H8: =IF(B8="","",IF(H8="",NOW(),H8)) -> 45550.204 | I8: =IFERROR(VLOOKUP(B8,'Runner List'!$B$3:$O$505,12,FALSE),0) -> 0.20833333 | M8: Female | N8: =COUNTIFS($G$4:$G$200,"MKT33",$D$4:$D$200,"Female") -> 25 | O8: 20-39 | P8: =COUNTIFS($G$4:$G$200,"MKT33",$D$4:$D$200,"Female",$E$4:$E$200,"20-39") -> 13 | R8: Female | S8: =COUNTIFS($G$4:$G$200,"MKT50",$D$4:$D$200,"Female") -> 9 | T8: 20-39 | U8: =COUNTIFS($G$4:$G$200,"MKT50",$D$4:$D$200,"Female",$E$4:$E$200,"20-39") -> 0
A9: 6 | B9: 5015 | C9: =IFERROR(VLOOKUP(B9,'Runner List'!$B$3:$OT$505,5,FALSE),0) -> JIAMJIT TANOMSAB | D9: =IFERROR(VLOOKUP(B9,'Runner List'!$B$3:$O$505,7,FALSE),0) -> Female | E9: =IFERROR(VLOOKUP(B9,'Runner List'!$B$3:$O$505,8,FALSE),0) -> 50-59 | F9: =IFERROR(VLOOKUP(B9,'Runner List'!$B$3:$O$505,9,FALSE),0) -> Thai | G9: =IFERROR(VLOOKUP(B9,'Runner List'!$B$3:$O$505,10,FALSE),0) -> MKT50 | H9: =IF(B9="","",IF(H9="",NOW(),H9)) -> 45550.204 | I9: =IFERROR(VLOOKUP(B9,'Runner List'!$B$3:$O$505,12,FALSE),0) -> 0.20833333 | O9: 40-49 | P9: =COUNTIFS($G$4:$G$200,"MKT33",$D$4:$D$200,"Female",$E$4:$E$200,"40-49") -> 7 | T9: 40-49 | U9: =COUNTIFS($G$4:$G$200,"MKT50",$D$4:$D$200,"Female",$E$4:$E$200,"40-49") -> 3
A10: 7 | B10: 5041 | C10: =IFERROR(VLOOKUP(B10,'Runner List'!$B$3:$OT$505,5,FALSE),0) -> ALAN FLENING | D10: =IFERROR(VLOOKUP(B10,'Runner List'!$B$3:$O$505,7,FALSE),0) -> Male | E10: =IFERROR(VLOOKUP(B10,'Runner List'!$B$3:$O$505,8,FALSE),0) -> 40-49 | F10: =IFERROR(VLOOKUP(B10,'Runner List'!$B$3:$O$505,9,FALSE),0) -> Australia | G10: =IFERROR(VLOOKUP(B10,'Runner List'!$B$3:$O$505,10,FALSE),0) -> MKT50 | H10: =IF(B10="","",IF(H10="",NOW(),H10)) -> 45550.204 | I10: =IFERROR(VLOOKUP(B10,'Runner List'!$B$3:$O$505,12,FALSE),0) -> 0.20833333 | O10: 50-59 | P10: =COUNTIFS($G$4:$G$200,"MKT33",$D$4:$D$200,"Female",$E$4:$E$200,"50-59") -> 4 | T10: 50-59 | U10: =COUNTIFS($G$4:$G$200,"MKT50",$D$4:$D$200,"Female",$E$4:$E$200,"50-59") -> 5
A11: 8 | B11: 5017 | C11: =IFERROR(VLOOKUP(B11,'Runner List'!$B$3:$OT$505,5,FALSE),0) -> SIRILAX ROMPHONGERN | D11: =IFERROR(VLOOKUP(B11,'Runner List'!$B$3:$O$505,7,FALSE),0) -> Female | E11: =IFERROR(VLOOKUP(B11,'Runner List'!$B$3:$O$505,8,FALSE),0) -> 50-59 | F11: =IFERROR(VLOOKUP(B11,'Runner List'!$B$3:$O$505,9,FALSE),0) -> Thai | G11: =IFERROR(VLOOKUP(B11,'Runner List'!$B$3:$O$505,10,FALSE),0) -> MKT50 | H11: =IF(B11="","",IF(H11="",NOW(),H11)) -> 45550.204 | I11: =IFERROR(VLOOKUP(B11,'Runner List'!$B$3:$O$505,12,FALSE),0) -> 0.20833333 | O11: 60 Plus | P11: =COUNTIFS($G$4:$G$200,"MKT33",$D$4:$D$200,"Female",$E$4:$E$200,"60 Plush") -> 0 | T11: 60 Plus | U11: =COUNTIFS($G$4:$G$200,"MKT50",$D$4:$D$200,"Female",$E$4:$E$200,"60 Plus") -> 1
A12: 9 | B12: 5046 | C12: =IFERROR(VLOOKUP(B12,'Runner List'!$B$3:$OT$505,5,FALSE),0) -> PATTHANAPICJI TRINWATTHAWORN | D12: =IFERROR(VLOOKUP(B12,'Runner List'!$B$3:$O$505,7,FALSE),0) -> Male | E12: =IFERROR(VLOOKUP(B12,'Runner List'!$B$3:$O$505,8,FALSE),0) -> 40-49 | F12: =IFERROR(VLOOKUP(B12,'Runner List'!$B$3:$O$505,9,FALSE),0) -> Thai | G12: =IFERROR(VLOOKUP(B12,'Runner List'!$B$3:$O$505,10,FALSE),0) -> MKT50 | H12: =IF(B12="","",IF(H12="",NOW(),H12)) -> 45550.204 | I12: =IFERROR(VLOOKUP(B12,'Runner List'!$B$3:$O$505,12,FALSE),0) -> 0.20833333 | M12: LGBTIQAN+ | N12: =COUNTIFS($G$4:$G$200,"MKT33",$D$4:$D$200,"LGBTIQAN+") -> 2 | O12: 20-39 | P12: N/A | R12: LGBTIQAN+ | S12: =COUNTIFS($H$4:$H$200,"MKT50",$E$4:$E$200,"LGBTIQAN+") -> 0 | T12: 20-39 | U12: N/A
A13: 10 | B13: 5034 | C13: =IFERROR(VLOOKUP(B13,'Runner List'!$B$3:$OT$505,5,FALSE),0) -> JEERAPHAN NONTAKA | D13: =IFERROR(VLOOKUP(B13,'Runner List'!$B$3:$O$505,7,FALSE),0) -> Male | E13: =IFERROR(VLOOKUP(B13,'Runner List'!$B$3:$O$505,8,FALSE),0) -> 20-39 | F13: =IFERROR(VLOOKUP(B13,'Runner List'!$B$3:$O$505,9,FALSE),0) -> Thai | G13: =IFERROR(VLOOKUP(B13,'Runner List'!$B$3:$O$505,10,FALSE),0) -> MKT50 | H13: =IF(B13="","",IF(H13="",NOW(),H13)) -> 45550.204 | I13: =IFERROR(VLOOKUP(B13,'Runner List'!$B$3:$O$505,12,FALSE),0) -> 0.20833333 | O13: 40-49 | P13: N/A | T13: 40-49 | U13: N/A
A14: 11 | B14: 5030 | C14: =IFERROR(VLOOKUP(B14,'Runner List'!$B$3:$OT$505,5,FALSE),0) -> WEERAWUT PHABMEK | D14: =IFERROR(VLOOKUP(B14,'Runner List'!$B$3:$O$505,7,FALSE),0) -> Male | E14: =IFERROR(VLOOKUP(B14,'Runner List'!$B$3:$O$505,8,FALSE),0) -> 50-59 | F14: =IFERROR(VLOOKUP(B14,'Runner List'!$B$3:$O$505,9,FALSE),0) -> Thai | G14: =IFERROR(VLOOKUP(B14,'Runner List'!$B$3:$O$505,10,FALSE),0) -> MKT50 | H14: =IF(B14="","",IF(H14="",NOW(),H14)) -> 45550.204 | I14: =IFERROR(VLOOKUP(B14,'Runner List'!$B$3:$O$505,12,FALSE),0) -> 0.20833333 | O14: 50-59 | P14: N/A | T14: 50-59 | U14: N/A
A15: 12 | B15: 5048 | C15: =IFERROR(VLOOKUP(B15,'Runner List'!$B$3:$OT$505,5,FALSE),0) -> SONGWUT BOAKHEM | D15: =IFERROR(VLOOKUP(B15,'Runner List'!$B$3:$O$505,7,FALSE),0) -> Male | E15: =IFERROR(VLOOKUP(B15,'Runner List'!$B$3:$O$505,8,FALSE),0) -> 60 Plus | F15: =IFERROR(VLOOKUP(B15,'Runner List'!$B$3:$O$505,9,FALSE),0) -> Thai | G15: =IFERROR(VLOOKUP(B15,'Runner List'!$B$3:$O$505,10,FALSE),0) -> MKT50 | H15: =IF(B15="","",IF(H15="",NOW(),H15)) -> 45550.204 | I15: =IFERROR(VLOOKUP(B15,'Runner List'!$B$3:$O$505,12,FALSE),0) -> 0.20833333 | O15: 60 Plus | P15: N/A | T15: 60 Plus | U15: N/A
A16: 13 | B16: 5032 | C16: =IFERROR(VLOOKUP(B16,'Runner List'!$B$3:$OT$505,5,FALSE),0) -> MARTIN RIEDINGER | D16: =IFERROR(VLOOKUP(B16,'Runner List'!$B$3:$O$505,7,FALSE),0) -> Male | E16: =IFERROR(VLOOKUP(B16,'Runner List'!$B$3:$O$505,8,FALSE),0) -> 40-49 | F16: =IFERROR(VLOOKUP(B16,'Runner List'!$B$3:$O$505,9,FALSE),0) -> German | G16: =IFERROR(VLOOKUP(B16,'Runner List'!$B$3:$O$505,10,FALSE),0) -> MKT50 | H16: =IF(B16="","",IF(H16="",NOW(),H16)) -> 45550.204 | I16: =IFERROR(VLOOKUP(B16,'Runner List'!$B$3:$O$505,12,FALSE),0) -> 0.20833333 | N16: =SUM(N4:N15) -> 74 | S16: =SUM(S4:S15) -> 34
A17: 14 | B17: 5044 | C17: =IFERROR(VLOOKUP(B17,'Runner List'!$B$3:$OT$505,5,FALSE),0) -> PHONGSATHON JEESOM | D17: =IFERROR(VLOOKUP(B17,'Runner List'!$B$3:$O$505,7,FALSE),0) -> Male | E17: =IFERROR(VLOOKUP(B17,'Runner List'!$B$3:$O$505,8,FALSE),0) -> 40-49 | F17: =IFERROR(VLOOKUP(B17,'Runner List'!$B$3:$O$505,9,FALSE),0) -> Thai | G17: =IFERROR(VLOOKUP(B17,'Runner List'!$B$3:$O$505,10,FALSE),0) -> MKT50 | H17: =IF(B17="","",IF(H17="",NOW(),H17)) -> 45550.204 | I17: =IFERROR(VLOOKUP(B17,'Runner List'!$B$3:$O$505,12,FALSE),0) -> 0.20833333
A18: 15 | B18: 5024 | C18: =IFERROR(VLOOKUP(B18,'Runner List'!$B$3:$OT$505,5,FALSE),0) -> ROSSARIN JINATHAM | D18: =IFERROR(VLOOKUP(B18,'Runner List'!$B$3:$O$505,7,FALSE),0) -> Female | E18: =IFERROR(VLOOKUP(B18,'Runner List'!$B$3:$O$505,8,FALSE),0) -> 40-49 | F18: =IFERROR(VLOOKUP(B18,'Runner List'!$B$3:$O$505,9,FALSE),0) -> Thai | G18: =IFERROR(VLOOKUP(B18,'Runner List'!$B$3:$O$505,10,FALSE),0) -> MKT50 | H18: =IF(B18="","",IF(H18="",NOW(),H18)) -> 45550.204 | I18: =IFERROR(VLOOKUP(B18,'Runner List'!$B$3:$O$505,12,FALSE),0) -> 0.20833333
A19: 16 | B19: 5045 | C19: =IFERROR(VLOOKUP(B19,'Runner List'!$B$3:$OT$505,5,FALSE),0) -> VEERAPONG PAKDEEPRASERT | D19: =IFERROR(VLOOKUP(B19,'Runner List'!$B$3:$O$505,7,FALSE),0) -> Male | E19: =IFERROR(VLOOKUP(B19,'Runner List'!$B$3:$O$505,8,FALSE),0) -> 40-49 | F19: =IFERROR(VLOOKUP(B19,'Runner List'!$B$3:$O$505,9,FALSE),0) -> Thai | G19: =IFERROR(VLOOKUP(B19,'Runner List'!$B$3:$O$505,10,FALSE),0) -> MKT50 | H19: =IF(B19="","",IF(H19="",NOW(),H19)) -> 45550.205 | I19: =IFERROR(VLOOKUP(B19,'Runner List'!$B$3:$O$505,12,FALSE),0) -> 0.20833333
A20: 17 | B20: 5037 | C20: =IFERROR(VLOOKUP(B20,'Runner List'!$B$3:$OT$505,5,FALSE),0) -> JITRA TOIM | D20: =IFERROR(VLOOKUP(B20,'Runner List'!$B$3:$O$505,7,FALSE),0) -> Female | E20: =IFERROR(VLOOKUP(B20,'Runner List'!$B$3:$O$505,8,FALSE),0) -> 40-49 | F20: =IFERROR(VLOOKUP(B20,'Runner List'!$B$3:$O$505,9,FALSE),0) -> Thai | G20: =IFERROR(VLOOKUP(B20,'Runner List'!$B$3:$O$505,10,FALSE),0) -> MKT50 | H20: =IF(B20="","",IF(H20="",NOW(),H20)) -> 45550.205 | I20: =IFERROR(VLOOKUP(B20,'Runner List'!$B$3:$O$505,12,FALSE),0) -> 0.20833333
A21: 18 | B21: 5022 | C21: =IFERROR(VLOOKUP(B21,'Runner List'!$B$3:$OT$505,5,FALSE),0) -> WEERAWAT SHATAREEYAKUL | D21: =IFERROR(VLOOKUP(B21,'Runner List'!$B$3:$O$505,7,FALSE),0) -> Male | E21: =IFERROR(VLOOKUP(B21,'Runner List'!$B$3:$O$505,8,FALSE),0) -> 40-49 | F21: =IFERROR(VLOOKUP(B21,'Runner List'!$B$3:$O$505,9,FALSE),0) -> Thai | G21: =IFERROR(VLOOKUP(B21,'Runner List'!$B$3:$O$505,10,FALSE),0) -> MKT50 | H21: =IF(B21="","",IF(H21="",NOW(),H21)) -> 45550.205 | I21: =IFERROR(VLOOKUP(B21,'Runner List'!$B$3:$O$505,12,FALSE),0) -> 0.20833333
A22: 19 | B22: 5049 | C22: =IFERROR(VLOOKUP(B22,'Runner List'!$B$3:$OT$505,5,FALSE),0) -> SURAPONG PORNPRADIT | D22: =IFERROR(VLOOKUP(B22,'Runner List'!$B$3:$O$505,7,FALSE),0) -> Male | E22: =IFERROR(VLOOKUP(B22,'Runner List'!$B$3:$O$505,8,FALSE),0) -> 60 Plus | F22: =IFERROR(VLOOKUP(B22,'Runner List'!$B$3:$O$505,9,FALSE),0) -> Thai | G22: =IFERROR(VLOOKUP(B22,'Runner List'!$B$3:$O$505,10,FALSE),0) -> MKT50 | H22: =IF(B22="","",IF(H22="",NOW(),H22)) -> 45550.205 | I22: =IFERROR(VLOOKUP(B22,'Runner List'!$B$3:$O$505,12,FALSE),0) -> 0.20833333
A23: 20 | B23: 5035 | C23: =IFERROR(VLOOKUP(B23,'Runner List'!$B$3:$OT$505,5,FALSE),0) -> PEERAPON BOONSRISOD | D23: =IFERROR(VLOOKUP(B23,'Runner List'!$B$3:$O$505,7,FALSE),0) -> Male | E23: =IFERROR(VLOOKUP(B23,'Runner List'!$B$3:$O$505,8,FALSE),0) -> 50-59 | F23: =IFERROR(VLOOKUP(B23,'Runner List'!$B$3:$O$505,9,FALSE),0) -> Thai | G23: =IFERROR(VLOOKUP(B23,'Runner List'!$B$3:$O$505,10,FALSE),0) -> MKT50 | H23: =IF(B23="","",IF(H23="",NOW(),H23)) -> 45550.205 | I23: =IFERROR(VLOOKUP(B23,'Runner List'!$B$3:$O$505,12,FALSE),0) -> 0.20833333
A24: 21 | B24: 5025 | C24: =IFERROR(VLOOKUP(B24,'Runner List'!$B$3:$OT$505,5,FALSE),0) -> NOTTHAKIT KASEE | D24: =IFERROR(VLOOKUP(B24,'Runner List'!$B$3:$O$505,7,FALSE),0) -> Male | E24: =IFERROR(VLOOKUP(B24,'Runner List'!$B$3:$O$505,8,FALSE),0) -> 50-59 | F24: =IFERROR(VLOOKUP(B24,'Runner List'!$B$3:$O$505,9,FALSE),0) -> Thai | G24: =IFERROR(VLOOKUP(B24,'Runner List'!$B$3:$O$505,10,FALSE),0) -> MKT50 | H24: =IF(B24="","",IF(H24="",NOW(),H24)) -> 45550.205 | I24: =IFERROR(VLOOKUP(B24,'Runner List'!$B$3:$O$505,12,FALSE),0) -> 0.20833333
A25: 22 | B25: 5039 | C25: =IFERROR(VLOOKUP(B25,'Runner List'!$B$3:$OT$505,5,FALSE),0) -> KITTIVUT KAEWPRASERT | D25: =IFERROR(VLOOKUP(B25,'Runner List'!$B$3:$O$505,7,FALSE),0) -> Male | E25: =IFERROR(VLOOKUP(B25,'Runner List'!$B$3:$O$505,8,FALSE),0) -> 40-49 | F25: =IFERROR(VLOOKUP(B25,'Runner List'!$B$3:$O$505,9,FALSE),0) -> Thai | G25: =IFERROR(VLOOKUP(B25,'Runner List'!$B$3:$O$505,10,FALSE),0) -> MKT50 | H25: =IF(B25="","",IF(H25="",NOW(),H25)) -> 45550.205 | I25: =IFERROR(VLOOKUP(B25,'Runner List'!$B$3:$O$505,12,FALSE),0) -> 0.20833333
A26: 23 | B26: 5021 | C26: =IFERROR(VLOOKUP(B26,'Runner List'!$B$3:$OT$505,5,FALSE),0) -> KANOKRUD GLANKWAHMDEE | D26: =IFERROR(VLOOKUP(B26,'Runner List'!$B$3:$O$505,7,FALSE),0) -> Female | E26: =IFERROR(VLOOKUP(B26,'Runner List'!$B$3:$O$505,8,FALSE),0) -> 60 Plus | F26: =IFERROR(VLOOKUP(B26,'Runner List'!$B$3:$O$505,9,FALSE),0) -> Thai | G26: =IFERROR(VLOOKUP(B26,'Runner List'!$B$3:$O$505,10,FALSE),0) -> MKT50 | H26: =IF(B26="","",IF(H26="",NOW(),H26)) -> 45550.205 | I26: =IFERROR(VLOOKUP(B26,'Runner List'!$B$3:$O$505,12,FALSE),0) -> 0.20833333
A27: 24 | B27: 5020 | C27: =IFERROR(VLOOKUP(B27,'Runner List'!$B$3:$OT$505,5,FALSE),0) -> BORWORNVIDHYA GLANKWAHMDEE | D27: =IFERROR(VLOOKUP(B27,'Runner List'!$B$3:$O$505,7,FALSE),0) -> Male | E27: =IFERROR(VLOOKUP(B27,'Runner List'!$B$3:$O$505,8,FALSE),0) -> 60 Plus | F27: =IFERROR(VLOOKUP(B27,'Runner List'!$B$3:$O$505,9,FALSE),0) -> Thai | G27: =IFERROR(VLOOKUP(B27,'Runner List'!$B$3:$O$505,10,FALSE),0) -> MKT50 | H27: =IF(B27="","",IF(H27="",NOW(),H27)) -> 45550.205 | I27: =IFERROR(VLOOKUP(B27,'Runner List'!$B$3:$O$505,12,FALSE),0) -> 0.20833333
A28: 25 | B28: 5027 | C28: =IFERROR(VLOOKUP(B28,'Runner List'!$B$3:$OT$505,5,FALSE),0) -> UMAPORN TIRAWAT | D28: =IFERROR(VLOOKUP(B28,'Runner List'!$B$3:$O$505,7,FALSE),0) -> Female | E28: =IFERROR(VLOOKUP(B28,'Runner List'!$B$3:$O$505,8,FALSE),0) -> 50-59 | F28: =IFERROR(VLOOKUP(B28,'Runner List'!$B$3:$O$505,9,FALSE),0) -> Thai | G28: =IFERROR(VLOOKUP(B28,'Runner List'!$B$3:$O$505,10,FALSE),0) -> MKT50 | H28: =IF(B28="","",IF(H28="",NOW(),H28)) -> 45550.205 | I28: =IFERROR(VLOOKUP(B28,'Runner List'!$B$3:$O$505,12,FALSE),0) -> 0.20833333
... A37: 34 | B37: 5042 | C37: =IFERROR(VLOOKUP(B37,'Runner List'!$B$3:$OT$505,5,FALSE),0) -> TIMOTHY EDWARDS | D37: =IFERROR(VLOOKUP(B37,'Runner List'!$B$3:$O$505,7,FALSE),0) -> Male | E37: =IFERROR(VLOOKUP(B37,'Runner List'!$B$3:$O$505,8,FALSE),0) -> 40-49 | F37: =IFERROR(VLOOKUP(B37,'Runner List'!$B$3:$O$505,9,FALSE),0) -> USA | G37: =IFERROR(VLOOKUP(B37,'Runner List'!$B$3:$O$505,10,FALSE),0) -> MKT50 | H37: =IF(B37="","",IF(H37="",NOW(),H37)) -> 45550.206 | I37: =IFERROR(VLOOKUP(B37,'Runner List'!$B$3:$O$505,12,FALSE),0) -> 0.20833333
A38: 35 | B38: 5031 | C38: =IFERROR(VLOOKUP(B38,'Runner List'!$B$3:$OT$505,5,FALSE),0) -> EAKKAMOL INTUSOPON | D38: =IFERROR(VLOOKUP(B38,'Runner List'!$B$3:$O$505,7,FALSE),0) -> Male | E38: =IFERROR(VLOOKUP(B38,'Runner List'!$B$3:$O$505,8,FALSE),0) -> 40-49 | F38: =IFERROR(VLOOKUP(B38,'Runner List'!$B$3:$O$505,9,FALSE),0) -> Thai | G38: =IFERROR(VLOOKUP(B38,'Runner List'!$B$3:$O$505,10,FALSE),0) -> MKT50 | H38: =IF(B38="","",IF(H38="",NOW(),H38)) -> 45550.207 | I38: =IFERROR(VLOOKUP(B38,'Runner List'!$B$3:$O$505,12,FALSE),0) -> 0.20833333 | BF38: 14000
A39: 36 | B39: 3348 | C39: =IFERROR(VLOOKUP(B39,'Runner List'!$B$3:$OT$505,5,FALSE),0) -> OLIVER HELM | D39: =IFERROR(VLOOKUP(B39,'Runner List'!$B$3:$O$505,7,FALSE),0) -> Male | E39: =IFERROR(VLOOKUP(B39,'Runner List'!$B$3:$O$505,8,FALSE),0) -> 20-39 | F39: =IFERROR(VLOOKUP(B39,'Runner List'!$B$3:$O$505,9,FALSE),0) -> New Zealand | G39: =IFERROR(VLOOKUP(B39,'Runner List'!$B$3:$O$505,10,FALSE),0) -> MKT33 | H39: =IF(B39="","",IF(H39="",NOW(),H39)) -> 45550.226 | I39: =IFERROR(VLOOKUP(B39,'Runner List'!$B$3:$O$505,12,FALSE),0) -> 0.22916667
A40: 37 | B40: 3301 | C40: =IFERROR(VLOOKUP(B40,'Runner List'!$B$3:$OT$505,5,FALSE),0) -> BLAKE WICHTOWSKI | D40: =IFERROR(VLOOKUP(B40,'Runner List'!$B$3:$O$505,7,FALSE),0) -> Male | E40: =IFERROR(VLOOKUP(B40,'Runner List'!$B$3:$O$505,8,FALSE),0) -> 20-39 | F40: =IFERROR(VLOOKUP(B40,'Runner List'!$B$3:$O$505,9,FALSE),0) -> Thai | G40: =IFERROR(VLOOKUP(B40,'Runner List'!$B$3:$O$505,10,FALSE),0) -> MKT33 | H40: =IF(B40="","",IF(H40="",NOW(),H40)) -> 45550.226 | I40: =IFERROR(VLOOKUP(B40,'Runner List'!$B$3:$O$505,12,FALSE),0) -> 0.22916667
A41: 38 | B41: 3368 | C41: =IFERROR(VLOOKUP(B41,'Runner List'!$B$3:$OT$505,5,FALSE),0) -> TOTSAPORN MUAMGNGAM | D41: =IFERROR(VLOOKUP(B41,'Runner List'!$B$3:$O$505,7,FALSE),0) -> Female | E41: =IFERROR(VLOOKUP(B41,'Runner List'!$B$3:$O$505,8,FALSE),0) -> 20-39 | F41: =IFERROR(VLOOKUP(B41,'Runner List'!$B$3:$O$505,9,FALSE),0) -> Thai | G41: =IFERROR(VLOOKUP(B41,'Runner List'!$B$3:$O$505,10,FALSE),0) -> MKT33 | H41: =IF(B41="","",IF(H41="",NOW(),H41)) -> 45550.226 | I41: =IFERROR(VLOOKUP(B41,'Runner List'!$B$3:$O$505,12,FALSE),0) -> 0.22916667
A42: 39 | B42: 3375 | C42: =IFERROR(VLOOKUP(B42,'Runner List'!$B$3:$OT$505,5,FALSE),0) -> BENYADA YOSHSINGCOME | D42: =IFERROR(VLOOKUP(B42,'Runner List'!$B$3:$O$505,7,FALSE),0) -> Female | E42: =IFERROR(VLOOKUP(B42,'Runner List'!$B$3:$O$505,8,FALSE),0) -> 40-49 | F42: =IFERROR(VLOOKUP(B42,'Runner List'!$B$3:$O$505,9,FALSE),0) -> Thai | G42: =IFERROR(VLOOKUP(B42,'Runner List'!$B$3:$O$505,10,FALSE),0) -> MKT33 | H42: =IF(B42="","",IF(H42="",NOW(),H42)) -> 45550.226 | I42: =IFERROR(VLOOKUP(B42,'Runner List'!$B$3:$O$505,12,FALSE),0) -> 0.22916667
A43: 40 | B43: 3374 | C43: =IFERROR(VLOOKUP(B43,'Runner List'!$B$3:$OT$505,5,FALSE),0) -> JULARRUCK LOMPAIBOON | D43: =IFERROR(VLOOKUP(B43,'Runner List'!$B$3:$O$505,7,FALSE),0) -> Female | E43: =IFERROR(VLOOKUP(B43,'Runner List'!$B$3:$O$505,8,FALSE),0) -> 60 Plus | F43: =IFERROR(VLOOKUP(B43,'Runner List'!$B$3:$O$505,9,FALSE),0) -> Thai | G43: =IFERROR(VLOOKUP(B43,'Runner List'!$B$3:$O$505,10,FALSE),0) -> MKT33 | H43: =IF(B43="","",IF(H43="",NOW(),H43)) -> 45550.226 | I43: =IFERROR(VLOOKUP(B43,'Runner List'!$B$3:$O$505,12,FALSE),0) -> 0.22916667
A44: 41 | B44: 3320 | C44: =IFERROR(VLOOKUP(B44,'Runner List'!$B$3:$OT$505,5,FALSE),0) -> VATCHARA PUMNOI | D44: =IFERROR(VLOOKUP(B44,'Runner List'!$B$3:$O$505,7,FALSE),0) -> Male | E44: =IFERROR(VLOOKUP(B44,'Runner List'!$B$3:$O$505,8,FALSE),0) -> 50-59 | F44: =IFERROR(VLOOKUP(B44,'Runner List'!$B$3:$O$505,9,FALSE),0) -> Thai | G44: =IFERROR(VLOOKUP(B44,'Runner List'!$B$3:$O$505,10,FALSE),0) -> MKT33 | H44: =IF(B44="","",IF(H44="",NOW(),H44)) -> 45550.226 | I44: =IFERROR(VLOOKUP(B44,'Runner List'!$B$3:$O$505,12,FALSE),0) -> 0.22916667
A45: 42 | B45: 3321 | C45: =IFERROR(VLOOKUP(B45,'Runner List'!$B$3:$OT$505,5,FALSE),0) -> KHAMNONG SEEDA | D45: =IFERROR(VLOOKUP(B45,'Runner List'!$B$3:$O$505,7,FALSE),0) -> Female | E45: =IFERROR(VLOOKUP(B45,'Runner List'!$B$3:$O$505,8,FALSE),0) -> 20-39 | F45: =IFERROR(VLOOKUP(B45,'Runner List'!$B$3:$O$505,9,FALSE),0) -> Thai | G45: =IFERROR(VLOOKUP(B45,'Runner List'!$B$3:$O$505,10,FALSE),0) -> MKT33 | H45: =IF(B45="","",IF(H45="",NOW(),H45)) -> 45550.226 | I45: =IFERROR(VLOOKUP(B45,'Runner List'!$B$3:$O$505,12,FALSE),0) -> 0.22916667
A46: 43 | B46: 3379 | C46: =IFERROR(VLOOKUP(B46,'Runner List'!$B$3:$OT$505,5,FALSE),0) -> ITTIPON UPPAPONG | D46: =IFERROR(VLOOKUP(B46,'Runner List'!$B$3:$O$505,7,FALSE),0) -> Male | E46: =IFERROR(VLOOKUP(B46,'Runner List'!$B$3:$O$505,8,FALSE),0) -> 20-39 | F46: =IFERROR(VLOOKUP(B46,'Runner List'!$B$3:$O$505,9,FALSE),0) -> Thai | G46: =IFERROR(VLOOKUP(B46,'Runner List'!$B$3:$O$505,10,FALSE),0) -> MKT33 | H46: =IF(B46="","",IF(H46="",NOW(),H46)) -> 45550.226 | I46: =IFERROR(VLOOKUP(B46,'Runner List'!$B$3:$O$505,12,FALSE),0) -> 0.22916667
A47: 44 | B47: 3341 | C47: =IFERROR(VLOOKUP(B47,'Runner List'!$B$3:$OT$505,5,FALSE),0) -> KAMOL WATTANAPANICH | D47: =IFERROR(VLOOKUP(B47,'Runner List'!$B$3:$O$505,7,FALSE),0) -> Male | E47: =IFERROR(VLOOKUP(B47,'Runner List'!$B$3:$O$505,8,FALSE),0) -> 50-59 | F47: =IFERROR(VLOOKUP(B47,'Runner List'!$B$3:$O$505,9,FALSE),0) -> Thai | G47: =IFERROR(VLOOKUP(B47,'Runner List'!$B$3:$O$505,10,FALSE),0) -> MKT33 | H47: =IF(B47="","",IF(H47="",NOW(),H47)) -> 45550.226 | I47: =IFERROR(VLOOKUP(B47,'Runner List'!$B$3:$O$505,12,FALSE),0) -> 0.22916667
A48: 45 | B48: 3390 | C48: =IFERROR(VLOOKUP(B48,'Runner List'!$B$3:$OT$505,5,FALSE),0) -> URAIWAN JINAPHO | D48: =IFERROR(VLOOKUP(B48,'Runner List'!$B$3:$O$505,7,FALSE),0) -> Female | E48: =IFERROR(VLOOKUP(B48,'Runner List'!$B$3:$O$505,8,FALSE),0) -> 20-39 | F48: =IFERROR(VLOOKUP(B48,'Runner List'!$B$3:$O$505,9,FALSE),0) -> Thai | G48: =IFERROR(VLOOKUP(B48,'Runner List'!$B$3:$O$505,10,FALSE),0) -> MKT33 | H48: =IF(B48="","",IF(H48="",NOW(),H48)) -> 45550.226 | I48: =IFERROR(VLOOKUP(B48,'Runner List'!$B$3:$O$505,12,FALSE),0) -> 0.22916667
...

Sheet (1)Check Bib
A1: CHECK BIB RUNNER "Mae Khanin Trail 2024" | M1: Check BIB Runner
A2: No. | B2: BIB Number | C2: Name Surname | D2: Name on BIB | E2: Gender | F2: Age Group | G2: Nationality | H2: Race | I2: Start Time
A3: ลำดับ | B3: หมายเลขแข่งขัน | C3: ชื่อ-นามสกุล | D3: ชื่อบนหมายเลขวิ่ง | E3: เพศ | F3: กลุ่มอายุ | G3: สัญชาติ | H3: ระยะแข่งขัน | I3: เวลาปล่อยตัว | M3: MKT33 | N3: =COUNTIF($H$4:$H$196,"MKT33") -> 72 | R3: MKT50 | S3: =COUNTIF($H$4:$H$196,"MKT50") -> 29
